package rpg.world.gen;

import java.util.Random;

import net.minecraft.block.Block;
import net.minecraft.world.World;
import net.minecraft.world.gen.feature.WorldGenerator;

public class WorldGenRandom extends WorldGenerator
{
	protected int[] GetValidSpawnBlocks() {
		return new int[] {
			0, Block.dirt.blockID, Block.sand.blockID
		};
	}

	public boolean LocationIsValidSpawn(World world, int i, int j, int k){
		int distanceToAir = 0;
		int checkID = world.getBlockId(i, j, k);

		while (checkID != 0){
			distanceToAir++;
			checkID = world.getBlockId(i, j + distanceToAir, k);
		}

		if (distanceToAir > 3){
			return false;
		}
		j += distanceToAir - 1;

		int blockID = world.getBlockId(i, j, k);
		int blockIDAbove = world.getBlockId(i, j+1, k);
		int blockIDBelow = world.getBlockId(i, j-1, k);
		for (int x : GetValidSpawnBlocks()){
			if (blockIDAbove != 0){
				return false;
			}
			if (blockID == x){
				return true;
			}else if (blockID == Block.snow.blockID && blockIDBelow == x){
				return true;
			}
		}
		return false;
	}

	public WorldGenRandom() { }

	public boolean generate(World world, Random rand, int i, int j, int k) {
		//check that each corner is one of the valid spawn blocks
		if(!LocationIsValidSpawn(world, i, j, k) || !LocationIsValidSpawn(world, i + 20, j, k) || !LocationIsValidSpawn(world, i + 20, j, k + 34) || !LocationIsValidSpawn(world, i, j, k + 34))
		{
			return false;
		}

		world.setBlock(i + 0, j + 0, k + 0, Block.stone.blockID);
		world.setBlock(i + 0, j + 0, k + 1, Block.stone.blockID);
		world.setBlock(i + 0, j + 0, k + 2, Block.stone.blockID);
		world.setBlock(i + 0, j + 0, k + 3, Block.stone.blockID);
		world.setBlock(i + 0, j + 0, k + 4, Block.stone.blockID);
		world.setBlock(i + 0, j + 0, k + 5, Block.stone.blockID);
		world.setBlock(i + 0, j + 0, k + 6, Block.stone.blockID);
		world.setBlock(i + 0, j + 0, k + 7, Block.stone.blockID);
		world.setBlock(i + 0, j + 0, k + 8, Block.stone.blockID);
		world.setBlock(i + 0, j + 0, k + 9, Block.stone.blockID);
		world.setBlock(i + 0, j + 0, k + 10, Block.stone.blockID);
		world.setBlock(i + 0, j + 0, k + 11, Block.stone.blockID);
		world.setBlock(i + 0, j + 0, k + 12, Block.stone.blockID);
		world.setBlock(i + 0, j + 0, k + 13, Block.stone.blockID);
		world.setBlock(i + 0, j + 0, k + 14, Block.stone.blockID);
		world.setBlock(i + 0, j + 0, k + 15, Block.stone.blockID);
		world.setBlock(i + 0, j + 0, k + 16, Block.stone.blockID);
		world.setBlock(i + 0, j + 0, k + 17, Block.stone.blockID);
		world.setBlock(i + 0, j + 0, k + 18, Block.stone.blockID);
		world.setBlock(i + 0, j + 0, k + 19, Block.stone.blockID);
		world.setBlock(i + 0, j + 0, k + 20, Block.stone.blockID);
		world.setBlock(i + 0, j + 0, k + 21, Block.stone.blockID);
		world.setBlock(i + 0, j + 0, k + 22, Block.stone.blockID);
		world.setBlock(i + 0, j + 0, k + 23, Block.stone.blockID);
		world.setBlock(i + 0, j + 0, k + 24, Block.stone.blockID);
		world.setBlock(i + 0, j + 0, k + 25, Block.stone.blockID);
		world.setBlock(i + 0, j + 0, k + 26, Block.stone.blockID);
		world.setBlock(i + 0, j + 0, k + 27, Block.stone.blockID);
		world.setBlock(i + 0, j + 0, k + 28, Block.stone.blockID);
		world.setBlock(i + 0, j + 0, k + 29, Block.stone.blockID);
		world.setBlock(i + 0, j + 0, k + 30, Block.stone.blockID);
		world.setBlock(i + 0, j + 0, k + 31, Block.stone.blockID);
		world.setBlock(i + 0, j + 0, k + 32, Block.stone.blockID);
		world.setBlock(i + 0, j + 0, k + 33, Block.stone.blockID);
		world.setBlock(i + 0, j + 0, k + 34, Block.stone.blockID);
		world.setBlock(i + 0, j + 1, k + 0, Block.stone.blockID);
		world.setBlock(i + 0, j + 1, k + 1, Block.stone.blockID);
		world.setBlock(i + 0, j + 1, k + 2, Block.stone.blockID);
		world.setBlock(i + 0, j + 1, k + 3, Block.stone.blockID);
		world.setBlock(i + 0, j + 1, k + 4, Block.stone.blockID);
		world.setBlock(i + 0, j + 1, k + 5, Block.stone.blockID);
		world.setBlock(i + 0, j + 1, k + 6, Block.stone.blockID);
		world.setBlock(i + 0, j + 1, k + 7, Block.stone.blockID);
		world.setBlock(i + 0, j + 1, k + 8, Block.stone.blockID);
		world.setBlock(i + 0, j + 1, k + 9, Block.stone.blockID);
		world.setBlock(i + 0, j + 1, k + 10, Block.stone.blockID);
		world.setBlock(i + 0, j + 1, k + 11, Block.stone.blockID);
		world.setBlock(i + 0, j + 1, k + 12, Block.stone.blockID);
		world.setBlock(i + 0, j + 1, k + 13, Block.stone.blockID);
		world.setBlock(i + 0, j + 1, k + 14, Block.stone.blockID);
		world.setBlock(i + 0, j + 1, k + 15, Block.stone.blockID);
		world.setBlock(i + 0, j + 1, k + 16, Block.stone.blockID);
		world.setBlock(i + 0, j + 1, k + 17, Block.stone.blockID);
		world.setBlock(i + 0, j + 1, k + 18, Block.stone.blockID);
		world.setBlock(i + 0, j + 1, k + 19, Block.stone.blockID);
		world.setBlock(i + 0, j + 1, k + 20, Block.stone.blockID);
		world.setBlock(i + 0, j + 1, k + 21, Block.stone.blockID);
		world.setBlock(i + 0, j + 1, k + 22, Block.stone.blockID);
		world.setBlock(i + 0, j + 1, k + 23, Block.stone.blockID);
		world.setBlock(i + 0, j + 1, k + 24, Block.stone.blockID);
		world.setBlock(i + 0, j + 1, k + 25, Block.stone.blockID);
		world.setBlock(i + 0, j + 1, k + 26, Block.stone.blockID);
		world.setBlock(i + 0, j + 1, k + 27, Block.stone.blockID);
		world.setBlock(i + 0, j + 1, k + 28, Block.stone.blockID);
		world.setBlock(i + 0, j + 1, k + 29, Block.stone.blockID);
		world.setBlock(i + 0, j + 1, k + 30, Block.stone.blockID);
		world.setBlock(i + 0, j + 1, k + 31, Block.stone.blockID);
		world.setBlock(i + 0, j + 1, k + 32, Block.stone.blockID);
		world.setBlock(i + 0, j + 1, k + 33, Block.stone.blockID);
		world.setBlock(i + 0, j + 1, k + 34, Block.stone.blockID);
		world.setBlock(i + 0, j + 2, k + 0, Block.stone.blockID);
		world.setBlock(i + 0, j + 2, k + 1, Block.stone.blockID);
		world.setBlock(i + 0, j + 2, k + 2, Block.stone.blockID);
		world.setBlock(i + 0, j + 2, k + 3, Block.stone.blockID);
		world.setBlock(i + 0, j + 2, k + 4, Block.stone.blockID);
		world.setBlock(i + 0, j + 2, k + 5, Block.stone.blockID);
		world.setBlock(i + 0, j + 2, k + 6, Block.stone.blockID);
		world.setBlock(i + 0, j + 2, k + 7, Block.stone.blockID);
		world.setBlock(i + 0, j + 2, k + 8, Block.stone.blockID);
		world.setBlock(i + 0, j + 2, k + 9, Block.stone.blockID);
		world.setBlock(i + 0, j + 2, k + 10, Block.stone.blockID);
		world.setBlock(i + 0, j + 2, k + 11, Block.stone.blockID);
		world.setBlock(i + 0, j + 2, k + 12, Block.stone.blockID);
		world.setBlock(i + 0, j + 2, k + 13, Block.stone.blockID);
		world.setBlock(i + 0, j + 2, k + 14, Block.stone.blockID);
		world.setBlock(i + 0, j + 2, k + 15, Block.stone.blockID);
		world.setBlock(i + 0, j + 2, k + 16, Block.stone.blockID);
		world.setBlock(i + 0, j + 2, k + 17, Block.stone.blockID);
		world.setBlock(i + 0, j + 2, k + 18, Block.stone.blockID);
		world.setBlock(i + 0, j + 2, k + 19, Block.stone.blockID);
		world.setBlock(i + 0, j + 2, k + 20, Block.stone.blockID);
		world.setBlock(i + 0, j + 2, k + 21, Block.stone.blockID);
		world.setBlock(i + 0, j + 2, k + 22, Block.stone.blockID);
		world.setBlock(i + 0, j + 2, k + 23, Block.stone.blockID);
		world.setBlock(i + 0, j + 2, k + 24, Block.stone.blockID);
		world.setBlock(i + 0, j + 2, k + 25, Block.stone.blockID);
		world.setBlock(i + 0, j + 2, k + 26, Block.stone.blockID);
		world.setBlock(i + 0, j + 2, k + 27, Block.stone.blockID);
		world.setBlock(i + 0, j + 2, k + 28, Block.stone.blockID);
		world.setBlock(i + 0, j + 2, k + 29, Block.stone.blockID);
		world.setBlock(i + 0, j + 2, k + 30, Block.stone.blockID);
		world.setBlock(i + 0, j + 2, k + 31, Block.stone.blockID);
		world.setBlock(i + 0, j + 2, k + 32, Block.stone.blockID);
		world.setBlock(i + 0, j + 2, k + 33, Block.stone.blockID);
		world.setBlock(i + 0, j + 2, k + 34, Block.stone.blockID);
		world.setBlock(i + 0, j + 3, k + 0, Block.stone.blockID);
		world.setBlock(i + 0, j + 3, k + 1, Block.stone.blockID);
		world.setBlock(i + 0, j + 3, k + 2, Block.stone.blockID);
		world.setBlock(i + 0, j + 3, k + 3, Block.stone.blockID);
		world.setBlock(i + 0, j + 3, k + 4, Block.stone.blockID);
		world.setBlock(i + 0, j + 3, k + 5, Block.stone.blockID);
		world.setBlock(i + 0, j + 3, k + 6, Block.stone.blockID);
		world.setBlock(i + 0, j + 3, k + 7, Block.stone.blockID);
		world.setBlock(i + 0, j + 3, k + 8, Block.stone.blockID);
		world.setBlock(i + 0, j + 3, k + 9, Block.stone.blockID);
		world.setBlock(i + 0, j + 3, k + 10, Block.stone.blockID);
		world.setBlock(i + 0, j + 3, k + 11, Block.stoneBrick.blockID);
		world.setBlock(i + 0, j + 3, k + 14, Block.stoneBrick.blockID);
		world.setBlock(i + 0, j + 3, k + 15, Block.stone.blockID);
		world.setBlock(i + 0, j + 3, k + 16, Block.stone.blockID);
		world.setBlock(i + 0, j + 3, k + 17, Block.stone.blockID);
		world.setBlock(i + 0, j + 3, k + 18, Block.stone.blockID);
		world.setBlock(i + 0, j + 3, k + 19, Block.stone.blockID);
		world.setBlock(i + 0, j + 3, k + 20, Block.stone.blockID);
		world.setBlock(i + 0, j + 3, k + 21, Block.stone.blockID);
		world.setBlock(i + 0, j + 3, k + 22, Block.stone.blockID);
		world.setBlock(i + 0, j + 3, k + 23, Block.stone.blockID);
		world.setBlock(i + 0, j + 3, k + 24, Block.stone.blockID);
		world.setBlock(i + 0, j + 3, k + 25, Block.stone.blockID);
		world.setBlock(i + 0, j + 3, k + 26, Block.stone.blockID);
		world.setBlock(i + 0, j + 3, k + 27, Block.stone.blockID);
		world.setBlock(i + 0, j + 3, k + 28, Block.stone.blockID);
		world.setBlock(i + 0, j + 3, k + 29, Block.stone.blockID);
		world.setBlock(i + 0, j + 3, k + 30, Block.stone.blockID);
		world.setBlock(i + 0, j + 3, k + 31, Block.stone.blockID);
		world.setBlock(i + 0, j + 3, k + 32, Block.stone.blockID);
		world.setBlock(i + 0, j + 3, k + 33, Block.stone.blockID);
		world.setBlock(i + 0, j + 3, k + 34, Block.stone.blockID);
		world.setBlock(i + 0, j + 4, k + 0, Block.stone.blockID);
		world.setBlock(i + 0, j + 4, k + 1, Block.stone.blockID);
		world.setBlock(i + 0, j + 4, k + 2, Block.stone.blockID);
		world.setBlock(i + 0, j + 4, k + 3, Block.stone.blockID);
		world.setBlock(i + 0, j + 4, k + 4, Block.stone.blockID);
		world.setBlock(i + 0, j + 4, k + 5, Block.stone.blockID);
		world.setBlock(i + 0, j + 4, k + 6, Block.stone.blockID);
		world.setBlock(i + 0, j + 4, k + 7, Block.stone.blockID);
		world.setBlock(i + 0, j + 4, k + 8, Block.stone.blockID);
		world.setBlock(i + 0, j + 4, k + 9, Block.stone.blockID);
		world.setBlock(i + 0, j + 4, k + 10, Block.stone.blockID);
		world.setBlock(i + 0, j + 4, k + 11, Block.stoneBrick.blockID);
		world.setBlock(i + 0, j + 4, k + 14, Block.stoneBrick.blockID);
		world.setBlock(i + 0, j + 4, k + 15, Block.stone.blockID);
		world.setBlock(i + 0, j + 4, k + 16, Block.stone.blockID);
		world.setBlock(i + 0, j + 4, k + 17, Block.stone.blockID);
		world.setBlock(i + 0, j + 4, k + 18, Block.stone.blockID);
		world.setBlock(i + 0, j + 4, k + 19, Block.stone.blockID);
		world.setBlock(i + 0, j + 4, k + 20, Block.stone.blockID);
		world.setBlock(i + 0, j + 4, k + 21, Block.stone.blockID);
		world.setBlock(i + 0, j + 4, k + 22, Block.stone.blockID);
		world.setBlock(i + 0, j + 4, k + 23, Block.stone.blockID);
		world.setBlock(i + 0, j + 4, k + 24, Block.stone.blockID);
		world.setBlock(i + 0, j + 4, k + 25, Block.stone.blockID);
		world.setBlock(i + 0, j + 4, k + 26, Block.stone.blockID);
		world.setBlock(i + 0, j + 4, k + 27, Block.stone.blockID);
		world.setBlock(i + 0, j + 4, k + 28, Block.stone.blockID);
		world.setBlock(i + 0, j + 4, k + 29, Block.stone.blockID);
		world.setBlock(i + 0, j + 4, k + 30, Block.stone.blockID);
		world.setBlock(i + 0, j + 4, k + 31, Block.stone.blockID);
		world.setBlock(i + 0, j + 4, k + 32, Block.stone.blockID);
		world.setBlock(i + 0, j + 4, k + 33, Block.stone.blockID);
		world.setBlock(i + 0, j + 4, k + 34, Block.stone.blockID);
		world.setBlock(i + 0, j + 5, k + 0, Block.stone.blockID);
		world.setBlock(i + 0, j + 5, k + 1, Block.stone.blockID);
		world.setBlock(i + 0, j + 5, k + 2, Block.stone.blockID);
		world.setBlock(i + 0, j + 5, k + 3, Block.stone.blockID);
		world.setBlock(i + 0, j + 5, k + 4, Block.stone.blockID);
		world.setBlock(i + 0, j + 5, k + 5, Block.stone.blockID);
		world.setBlock(i + 0, j + 5, k + 6, Block.stone.blockID);
		world.setBlock(i + 0, j + 5, k + 7, Block.stone.blockID);
		world.setBlock(i + 0, j + 5, k + 8, Block.stone.blockID);
		world.setBlock(i + 0, j + 5, k + 9, Block.stone.blockID);
		world.setBlock(i + 0, j + 5, k + 10, Block.stone.blockID);
		world.setBlockMetadataWithNotify(i + 0, j + 5, k + 11, Block.stoneBrick.blockID, 2);
		world.setBlockMetadataWithNotify(i + 0, j + 5, k + 14, Block.stoneBrick.blockID, 1);
		world.setBlock(i + 0, j + 5, k + 15, Block.stone.blockID);
		world.setBlock(i + 0, j + 5, k + 16, Block.stone.blockID);
		world.setBlock(i + 0, j + 5, k + 17, Block.stone.blockID);
		world.setBlock(i + 0, j + 5, k + 18, Block.stone.blockID);
		world.setBlock(i + 0, j + 5, k + 19, Block.stone.blockID);
		world.setBlock(i + 0, j + 5, k + 20, Block.stone.blockID);
		world.setBlock(i + 0, j + 5, k + 21, Block.stone.blockID);
		world.setBlock(i + 0, j + 5, k + 22, Block.stone.blockID);
		world.setBlock(i + 0, j + 5, k + 23, Block.stone.blockID);
		world.setBlock(i + 0, j + 5, k + 24, Block.stone.blockID);
		world.setBlock(i + 0, j + 5, k + 25, Block.stone.blockID);
		world.setBlock(i + 0, j + 5, k + 26, Block.stone.blockID);
		world.setBlock(i + 0, j + 5, k + 27, Block.stone.blockID);
		world.setBlock(i + 0, j + 5, k + 28, Block.stone.blockID);
		world.setBlock(i + 0, j + 5, k + 29, Block.stone.blockID);
		world.setBlock(i + 0, j + 5, k + 30, Block.stone.blockID);
		world.setBlock(i + 0, j + 5, k + 31, Block.stone.blockID);
		world.setBlock(i + 0, j + 5, k + 32, Block.stone.blockID);
		world.setBlock(i + 0, j + 5, k + 33, Block.stone.blockID);
		world.setBlock(i + 0, j + 5, k + 34, Block.stone.blockID);
		world.setBlock(i + 0, j + 6, k + 0, Block.stone.blockID);
		world.setBlock(i + 0, j + 6, k + 1, Block.stone.blockID);
		world.setBlock(i + 0, j + 6, k + 2, Block.stone.blockID);
		world.setBlock(i + 0, j + 6, k + 3, Block.stone.blockID);
		world.setBlock(i + 0, j + 6, k + 4, Block.stone.blockID);
		world.setBlock(i + 0, j + 6, k + 5, Block.stone.blockID);
		world.setBlock(i + 0, j + 6, k + 6, Block.stone.blockID);
		world.setBlock(i + 0, j + 6, k + 7, Block.stone.blockID);
		world.setBlock(i + 0, j + 6, k + 8, Block.stone.blockID);
		world.setBlock(i + 0, j + 6, k + 9, Block.stone.blockID);
		world.setBlock(i + 0, j + 6, k + 10, Block.stone.blockID);
		world.setBlock(i + 0, j + 6, k + 11, Block.stone.blockID);
		world.setBlock(i + 0, j + 6, k + 12, Block.stoneBrick.blockID);
		world.setBlock(i + 0, j + 6, k + 13, Block.stone.blockID);
		world.setBlock(i + 0, j + 6, k + 14, Block.stone.blockID);
		world.setBlock(i + 0, j + 6, k + 15, Block.stone.blockID);
		world.setBlock(i + 0, j + 6, k + 16, Block.stone.blockID);
		world.setBlock(i + 0, j + 6, k + 17, Block.stone.blockID);
		world.setBlock(i + 0, j + 6, k + 18, Block.stone.blockID);
		world.setBlock(i + 0, j + 6, k + 19, Block.stone.blockID);
		world.setBlock(i + 0, j + 6, k + 20, Block.stone.blockID);
		world.setBlock(i + 0, j + 6, k + 21, Block.stone.blockID);
		world.setBlock(i + 0, j + 6, k + 22, Block.stone.blockID);
		world.setBlock(i + 0, j + 6, k + 23, Block.stone.blockID);
		world.setBlock(i + 0, j + 6, k + 24, Block.stone.blockID);
		world.setBlock(i + 0, j + 6, k + 25, Block.stone.blockID);
		world.setBlock(i + 0, j + 6, k + 26, Block.stone.blockID);
		world.setBlock(i + 0, j + 6, k + 27, Block.stone.blockID);
		world.setBlock(i + 0, j + 6, k + 28, Block.stone.blockID);
		world.setBlock(i + 0, j + 6, k + 29, Block.stone.blockID);
		world.setBlock(i + 0, j + 6, k + 30, Block.stone.blockID);
		world.setBlock(i + 0, j + 6, k + 31, Block.stone.blockID);
		world.setBlock(i + 0, j + 6, k + 32, Block.stone.blockID);
		world.setBlock(i + 0, j + 6, k + 33, Block.stone.blockID);
		world.setBlock(i + 0, j + 6, k + 34, Block.stone.blockID);
		world.setBlock(i + 0, j + 7, k + 0, Block.stone.blockID);
		world.setBlock(i + 0, j + 7, k + 1, Block.stone.blockID);
		world.setBlock(i + 0, j + 7, k + 2, Block.stone.blockID);
		world.setBlock(i + 0, j + 7, k + 3, Block.stone.blockID);
		world.setBlock(i + 0, j + 7, k + 4, Block.stone.blockID);
		world.setBlock(i + 0, j + 7, k + 5, Block.stone.blockID);
		world.setBlock(i + 0, j + 7, k + 6, Block.stone.blockID);
		world.setBlock(i + 0, j + 7, k + 7, Block.stone.blockID);
		world.setBlock(i + 0, j + 7, k + 8, Block.stone.blockID);
		world.setBlock(i + 0, j + 7, k + 9, Block.stone.blockID);
		world.setBlock(i + 0, j + 7, k + 10, Block.stone.blockID);
		world.setBlock(i + 0, j + 7, k + 11, Block.stone.blockID);
		world.setBlock(i + 0, j + 7, k + 12, Block.stone.blockID);
		world.setBlock(i + 0, j + 7, k + 13, Block.stone.blockID);
		world.setBlock(i + 0, j + 7, k + 14, Block.stone.blockID);
		world.setBlock(i + 0, j + 7, k + 15, Block.stone.blockID);
		world.setBlock(i + 0, j + 7, k + 16, Block.stone.blockID);
		world.setBlock(i + 0, j + 7, k + 17, Block.stone.blockID);
		world.setBlock(i + 0, j + 7, k + 18, Block.stone.blockID);
		world.setBlock(i + 0, j + 7, k + 19, Block.stone.blockID);
		world.setBlock(i + 0, j + 7, k + 20, Block.stone.blockID);
		world.setBlock(i + 0, j + 7, k + 21, Block.stone.blockID);
		world.setBlock(i + 0, j + 7, k + 22, Block.stone.blockID);
		world.setBlock(i + 0, j + 7, k + 23, Block.stone.blockID);
		world.setBlock(i + 0, j + 7, k + 24, Block.stone.blockID);
		world.setBlock(i + 0, j + 7, k + 25, Block.stone.blockID);
		world.setBlock(i + 0, j + 7, k + 26, Block.stone.blockID);
		world.setBlock(i + 0, j + 7, k + 27, Block.stone.blockID);
		world.setBlock(i + 0, j + 7, k + 28, Block.stone.blockID);
		world.setBlock(i + 0, j + 7, k + 29, Block.stone.blockID);
		world.setBlock(i + 0, j + 7, k + 30, Block.stone.blockID);
		world.setBlock(i + 0, j + 7, k + 31, Block.stone.blockID);
		world.setBlock(i + 0, j + 7, k + 32, Block.stone.blockID);
		world.setBlock(i + 0, j + 7, k + 33, Block.stone.blockID);
		world.setBlock(i + 0, j + 7, k + 34, Block.stone.blockID);
		world.setBlock(i + 0, j + 8, k + 0, Block.stone.blockID);
		world.setBlock(i + 0, j + 8, k + 1, Block.stone.blockID);
		world.setBlock(i + 0, j + 8, k + 2, Block.stone.blockID);
		world.setBlock(i + 0, j + 8, k + 3, Block.stone.blockID);
		world.setBlock(i + 0, j + 8, k + 4, Block.stone.blockID);
		world.setBlock(i + 0, j + 8, k + 5, Block.stone.blockID);
		world.setBlock(i + 0, j + 8, k + 6, Block.stone.blockID);
		world.setBlock(i + 0, j + 8, k + 7, Block.stone.blockID);
		world.setBlock(i + 0, j + 8, k + 8, Block.stone.blockID);
		world.setBlock(i + 0, j + 8, k + 9, Block.stone.blockID);
		world.setBlock(i + 0, j + 8, k + 10, Block.stone.blockID);
		world.setBlock(i + 0, j + 8, k + 11, Block.stone.blockID);
		world.setBlock(i + 0, j + 8, k + 12, Block.stone.blockID);
		world.setBlock(i + 0, j + 8, k + 13, Block.stone.blockID);
		world.setBlock(i + 0, j + 8, k + 14, Block.stone.blockID);
		world.setBlock(i + 0, j + 8, k + 15, Block.stone.blockID);
		world.setBlock(i + 0, j + 8, k + 16, Block.stone.blockID);
		world.setBlock(i + 0, j + 8, k + 17, Block.stone.blockID);
		world.setBlock(i + 0, j + 8, k + 18, Block.stone.blockID);
		world.setBlock(i + 0, j + 8, k + 19, Block.stone.blockID);
		world.setBlock(i + 0, j + 8, k + 20, Block.stone.blockID);
		world.setBlock(i + 0, j + 8, k + 21, Block.stone.blockID);
		world.setBlock(i + 0, j + 8, k + 22, Block.stone.blockID);
		world.setBlock(i + 0, j + 8, k + 23, Block.stone.blockID);
		world.setBlock(i + 0, j + 8, k + 24, Block.stone.blockID);
		world.setBlock(i + 0, j + 8, k + 25, Block.stone.blockID);
		world.setBlock(i + 0, j + 8, k + 26, Block.stone.blockID);
		world.setBlock(i + 0, j + 8, k + 27, Block.stone.blockID);
		world.setBlock(i + 0, j + 8, k + 28, Block.stone.blockID);
		world.setBlock(i + 0, j + 8, k + 29, Block.stone.blockID);
		world.setBlock(i + 0, j + 8, k + 30, Block.stone.blockID);
		world.setBlock(i + 0, j + 8, k + 31, Block.stone.blockID);
		world.setBlock(i + 0, j + 8, k + 32, Block.stone.blockID);
		world.setBlock(i + 0, j + 8, k + 33, Block.stone.blockID);
		world.setBlock(i + 0, j + 8, k + 34, Block.stone.blockID);
		world.setBlock(i + 0, j + 9, k + 0, Block.stone.blockID);
		world.setBlock(i + 0, j + 9, k + 1, Block.stone.blockID);
		world.setBlock(i + 0, j + 9, k + 2, Block.stone.blockID);
		world.setBlock(i + 0, j + 9, k + 3, Block.stone.blockID);
		world.setBlock(i + 0, j + 9, k + 4, Block.stone.blockID);
		world.setBlock(i + 0, j + 9, k + 5, Block.stone.blockID);
		world.setBlock(i + 0, j + 9, k + 6, Block.stone.blockID);
		world.setBlock(i + 0, j + 9, k + 7, Block.stone.blockID);
		world.setBlock(i + 0, j + 9, k + 8, Block.stone.blockID);
		world.setBlock(i + 0, j + 9, k + 9, Block.stone.blockID);
		world.setBlock(i + 0, j + 9, k + 10, Block.stone.blockID);
		world.setBlock(i + 0, j + 9, k + 11, Block.stone.blockID);
		world.setBlock(i + 0, j + 9, k + 12, Block.stone.blockID);
		world.setBlock(i + 0, j + 9, k + 13, Block.stone.blockID);
		world.setBlock(i + 0, j + 9, k + 14, Block.stone.blockID);
		world.setBlock(i + 0, j + 9, k + 15, Block.stone.blockID);
		world.setBlock(i + 0, j + 9, k + 16, Block.stone.blockID);
		world.setBlock(i + 0, j + 9, k + 17, Block.stone.blockID);
		world.setBlock(i + 0, j + 9, k + 18, Block.stone.blockID);
		world.setBlock(i + 0, j + 9, k + 19, Block.stone.blockID);
		world.setBlock(i + 0, j + 9, k + 20, Block.stone.blockID);
		world.setBlock(i + 0, j + 9, k + 21, Block.stone.blockID);
		world.setBlock(i + 0, j + 9, k + 22, Block.stone.blockID);
		world.setBlock(i + 0, j + 9, k + 23, Block.stone.blockID);
		world.setBlock(i + 0, j + 9, k + 24, Block.stone.blockID);
		world.setBlock(i + 0, j + 9, k + 25, Block.stone.blockID);
		world.setBlock(i + 0, j + 9, k + 26, Block.stone.blockID);
		world.setBlock(i + 0, j + 9, k + 27, Block.stone.blockID);
		world.setBlock(i + 0, j + 9, k + 28, Block.stone.blockID);
		world.setBlock(i + 0, j + 9, k + 29, Block.stone.blockID);
		world.setBlock(i + 0, j + 9, k + 30, Block.stone.blockID);
		world.setBlock(i + 0, j + 9, k + 31, Block.stone.blockID);
		world.setBlock(i + 0, j + 9, k + 32, Block.stone.blockID);
		world.setBlock(i + 0, j + 9, k + 33, Block.stone.blockID);
		world.setBlock(i + 0, j + 9, k + 34, Block.stone.blockID);
		world.setBlock(i + 0, j + 10, k + 0, Block.stone.blockID);
		world.setBlock(i + 0, j + 10, k + 1, Block.stone.blockID);
		world.setBlock(i + 0, j + 10, k + 2, Block.stone.blockID);
		world.setBlock(i + 0, j + 10, k + 3, Block.stone.blockID);
		world.setBlock(i + 0, j + 10, k + 4, Block.stone.blockID);
		world.setBlock(i + 0, j + 10, k + 5, Block.stone.blockID);
		world.setBlock(i + 0, j + 10, k + 6, Block.stone.blockID);
		world.setBlock(i + 0, j + 10, k + 7, Block.stone.blockID);
		world.setBlock(i + 0, j + 10, k + 8, Block.stone.blockID);
		world.setBlock(i + 0, j + 10, k + 9, Block.stone.blockID);
		world.setBlock(i + 0, j + 10, k + 10, Block.stone.blockID);
		world.setBlock(i + 0, j + 10, k + 11, Block.stone.blockID);
		world.setBlock(i + 0, j + 10, k + 12, Block.stone.blockID);
		world.setBlock(i + 0, j + 10, k + 13, Block.stone.blockID);
		world.setBlock(i + 0, j + 10, k + 14, Block.stone.blockID);
		world.setBlock(i + 0, j + 10, k + 15, Block.stone.blockID);
		world.setBlock(i + 0, j + 10, k + 16, Block.stone.blockID);
		world.setBlock(i + 0, j + 10, k + 17, Block.stone.blockID);
		world.setBlock(i + 0, j + 10, k + 18, Block.stone.blockID);
		world.setBlock(i + 0, j + 10, k + 19, Block.stone.blockID);
		world.setBlock(i + 0, j + 10, k + 20, Block.stone.blockID);
		world.setBlock(i + 0, j + 10, k + 21, Block.stone.blockID);
		world.setBlock(i + 0, j + 10, k + 22, Block.stone.blockID);
		world.setBlock(i + 0, j + 10, k + 23, Block.stone.blockID);
		world.setBlock(i + 0, j + 10, k + 24, Block.stone.blockID);
		world.setBlock(i + 0, j + 10, k + 25, Block.stoneBrick.blockID);
		world.setBlock(i + 0, j + 10, k + 26, Block.stoneBrick.blockID);
		world.setBlock(i + 0, j + 10, k + 27, Block.stoneBrick.blockID);
		world.setBlock(i + 0, j + 10, k + 28, Block.stoneBrick.blockID);
		world.setBlock(i + 0, j + 10, k + 29, Block.stoneBrick.blockID);
		world.setBlock(i + 0, j + 10, k + 30, Block.stoneBrick.blockID);
		world.setBlock(i + 0, j + 10, k + 31, Block.stoneBrick.blockID);
		world.setBlockMetadataWithNotify(i + 0, j + 10, k + 32, Block.stoneBrick.blockID, 2);
		world.setBlock(i + 0, j + 10, k + 33, Block.stoneBrick.blockID);
		world.setBlock(i + 0, j + 10, k + 34, Block.stone.blockID);
		world.setBlock(i + 0, j + 11, k + 0, Block.stone.blockID);
		world.setBlock(i + 0, j + 11, k + 1, Block.stone.blockID);
		world.setBlock(i + 0, j + 11, k + 2, Block.stone.blockID);
		world.setBlock(i + 0, j + 11, k + 3, Block.stone.blockID);
		world.setBlock(i + 0, j + 11, k + 4, Block.stone.blockID);
		world.setBlock(i + 0, j + 11, k + 5, Block.stone.blockID);
		world.setBlock(i + 0, j + 11, k + 6, Block.stone.blockID);
		world.setBlock(i + 0, j + 11, k + 7, Block.stone.blockID);
		world.setBlock(i + 0, j + 11, k + 8, Block.stone.blockID);
		world.setBlock(i + 0, j + 11, k + 9, Block.stone.blockID);
		world.setBlock(i + 0, j + 11, k + 10, Block.stone.blockID);
		world.setBlock(i + 0, j + 11, k + 11, Block.stone.blockID);
		world.setBlock(i + 0, j + 11, k + 12, Block.stone.blockID);
		world.setBlock(i + 0, j + 11, k + 13, Block.stone.blockID);
		world.setBlock(i + 0, j + 11, k + 14, Block.stone.blockID);
		world.setBlock(i + 0, j + 11, k + 15, Block.stone.blockID);
		world.setBlock(i + 0, j + 11, k + 16, Block.stone.blockID);
		world.setBlock(i + 0, j + 11, k + 17, Block.stone.blockID);
		world.setBlock(i + 0, j + 11, k + 18, Block.stone.blockID);
		world.setBlock(i + 0, j + 11, k + 19, Block.stone.blockID);
		world.setBlock(i + 0, j + 11, k + 20, Block.stone.blockID);
		world.setBlock(i + 0, j + 11, k + 21, Block.stone.blockID);
		world.setBlock(i + 0, j + 11, k + 22, Block.stone.blockID);
		world.setBlock(i + 0, j + 11, k + 23, Block.stone.blockID);
		world.setBlock(i + 0, j + 11, k + 24, Block.stone.blockID);
		world.setBlock(i + 0, j + 11, k + 25, Block.stoneBrick.blockID);
		world.setBlock(i + 0, j + 11, k + 26, Block.stoneBrick.blockID);
		world.setBlock(i + 0, j + 11, k + 27, Block.stoneBrick.blockID);
		world.setBlock(i + 0, j + 11, k + 28, Block.stoneBrick.blockID);
		world.setBlock(i + 0, j + 11, k + 29, Block.stoneBrick.blockID);
		world.setBlock(i + 0, j + 11, k + 30, Block.stoneBrick.blockID);
		world.setBlock(i + 0, j + 11, k + 31, Block.stoneBrick.blockID);
		world.setBlockMetadataWithNotify(i + 0, j + 11, k + 32, Block.stoneBrick.blockID, 2);
		world.setBlock(i + 0, j + 11, k + 33, Block.stoneBrick.blockID);
		world.setBlock(i + 0, j + 11, k + 34, Block.stone.blockID);
		world.setBlock(i + 0, j + 12, k + 0, Block.stone.blockID);
		world.setBlock(i + 0, j + 12, k + 1, Block.stone.blockID);
		world.setBlock(i + 0, j + 12, k + 2, Block.stone.blockID);
		world.setBlock(i + 0, j + 12, k + 3, Block.stone.blockID);
		world.setBlock(i + 0, j + 12, k + 4, Block.stone.blockID);
		world.setBlock(i + 0, j + 12, k + 5, Block.stone.blockID);
		world.setBlock(i + 0, j + 12, k + 6, Block.stone.blockID);
		world.setBlock(i + 0, j + 12, k + 7, Block.stone.blockID);
		world.setBlock(i + 0, j + 12, k + 8, Block.stone.blockID);
		world.setBlock(i + 0, j + 12, k + 9, Block.stone.blockID);
		world.setBlock(i + 0, j + 12, k + 10, Block.stone.blockID);
		world.setBlock(i + 0, j + 12, k + 11, Block.stone.blockID);
		world.setBlock(i + 0, j + 12, k + 12, Block.stone.blockID);
		world.setBlock(i + 0, j + 12, k + 13, Block.stone.blockID);
		world.setBlock(i + 0, j + 12, k + 14, Block.stone.blockID);
		world.setBlock(i + 0, j + 12, k + 15, Block.stone.blockID);
		world.setBlock(i + 0, j + 12, k + 16, Block.stone.blockID);
		world.setBlock(i + 0, j + 12, k + 17, Block.stone.blockID);
		world.setBlock(i + 0, j + 12, k + 18, Block.stone.blockID);
		world.setBlock(i + 0, j + 12, k + 19, Block.stone.blockID);
		world.setBlock(i + 0, j + 12, k + 20, Block.stone.blockID);
		world.setBlock(i + 0, j + 12, k + 21, Block.stone.blockID);
		world.setBlock(i + 0, j + 12, k + 22, Block.stone.blockID);
		world.setBlock(i + 0, j + 12, k + 23, Block.stone.blockID);
		world.setBlock(i + 0, j + 12, k + 24, Block.stone.blockID);
		world.setBlock(i + 0, j + 12, k + 25, Block.stoneBrick.blockID);
		world.setBlock(i + 0, j + 12, k + 26, Block.stoneBrick.blockID);
		world.setBlock(i + 0, j + 12, k + 27, Block.stone.blockID);
		world.setBlock(i + 0, j + 12, k + 28, Block.stoneBrick.blockID);
		world.setBlock(i + 0, j + 12, k + 29, Block.stoneBrick.blockID);
		world.setBlock(i + 0, j + 12, k + 30, Block.stoneBrick.blockID);
		world.setBlock(i + 0, j + 12, k + 31, Block.stoneBrick.blockID);
		world.setBlock(i + 0, j + 12, k + 32, Block.stoneBrick.blockID);
		world.setBlock(i + 0, j + 12, k + 33, Block.stoneBrick.blockID);
		world.setBlock(i + 0, j + 12, k + 34, Block.stone.blockID);
		world.setBlock(i + 0, j + 13, k + 0, Block.stone.blockID);
		world.setBlock(i + 0, j + 13, k + 1, Block.stone.blockID);
		world.setBlock(i + 0, j + 13, k + 2, Block.stone.blockID);
		world.setBlock(i + 0, j + 13, k + 3, Block.stone.blockID);
		world.setBlock(i + 0, j + 13, k + 4, Block.stone.blockID);
		world.setBlock(i + 0, j + 13, k + 5, Block.stone.blockID);
		world.setBlock(i + 0, j + 13, k + 6, Block.stone.blockID);
		world.setBlock(i + 0, j + 13, k + 7, Block.stone.blockID);
		world.setBlock(i + 0, j + 13, k + 8, Block.stone.blockID);
		world.setBlock(i + 0, j + 13, k + 9, Block.stone.blockID);
		world.setBlock(i + 0, j + 13, k + 10, Block.stone.blockID);
		world.setBlock(i + 0, j + 13, k + 11, Block.stone.blockID);
		world.setBlock(i + 0, j + 13, k + 12, Block.stone.blockID);
		world.setBlock(i + 0, j + 13, k + 13, Block.stone.blockID);
		world.setBlock(i + 0, j + 13, k + 14, Block.stone.blockID);
		world.setBlock(i + 0, j + 13, k + 15, Block.stone.blockID);
		world.setBlock(i + 0, j + 13, k + 16, Block.stone.blockID);
		world.setBlock(i + 0, j + 13, k + 17, Block.stone.blockID);
		world.setBlock(i + 0, j + 13, k + 18, Block.stone.blockID);
		world.setBlock(i + 0, j + 13, k + 19, Block.stone.blockID);
		world.setBlock(i + 0, j + 13, k + 20, Block.stone.blockID);
		world.setBlock(i + 0, j + 13, k + 21, Block.stone.blockID);
		world.setBlock(i + 0, j + 13, k + 22, Block.stone.blockID);
		world.setBlock(i + 0, j + 13, k + 23, Block.stone.blockID);
		world.setBlock(i + 0, j + 13, k + 24, Block.stone.blockID);
		world.setBlock(i + 0, j + 13, k + 25, Block.stoneBrick.blockID);
		world.setBlock(i + 0, j + 13, k + 26, Block.stone.blockID);
		world.setBlock(i + 0, j + 13, k + 27, Block.stone.blockID);
		world.setBlock(i + 0, j + 13, k + 28, Block.stone.blockID);
		world.setBlock(i + 0, j + 13, k + 29, Block.stoneBrick.blockID);
		world.setBlock(i + 0, j + 13, k + 30, Block.stoneBrick.blockID);
		world.setBlock(i + 0, j + 13, k + 31, Block.stoneBrick.blockID);
		world.setBlock(i + 0, j + 13, k + 32, Block.stoneBrick.blockID);
		world.setBlock(i + 0, j + 13, k + 33, Block.stoneBrick.blockID);
		world.setBlock(i + 0, j + 13, k + 34, Block.stone.blockID);
		world.setBlock(i + 0, j + 14, k + 0, Block.stone.blockID);
		world.setBlock(i + 0, j + 14, k + 1, Block.stone.blockID);
		world.setBlock(i + 0, j + 14, k + 2, Block.stone.blockID);
		world.setBlock(i + 0, j + 14, k + 3, Block.stone.blockID);
		world.setBlock(i + 0, j + 14, k + 4, Block.stone.blockID);
		world.setBlock(i + 0, j + 14, k + 5, Block.stone.blockID);
		world.setBlock(i + 0, j + 14, k + 6, Block.stone.blockID);
		world.setBlock(i + 0, j + 14, k + 7, Block.stone.blockID);
		world.setBlock(i + 0, j + 14, k + 8, Block.stone.blockID);
		world.setBlock(i + 0, j + 14, k + 9, Block.stone.blockID);
		world.setBlock(i + 0, j + 14, k + 10, Block.stone.blockID);
		world.setBlock(i + 0, j + 14, k + 11, Block.stone.blockID);
		world.setBlock(i + 0, j + 14, k + 12, Block.stone.blockID);
		world.setBlock(i + 0, j + 14, k + 13, Block.stone.blockID);
		world.setBlock(i + 0, j + 14, k + 14, Block.stone.blockID);
		world.setBlock(i + 0, j + 14, k + 15, Block.stone.blockID);
		world.setBlock(i + 0, j + 14, k + 16, Block.stone.blockID);
		world.setBlock(i + 0, j + 14, k + 17, Block.stone.blockID);
		world.setBlock(i + 0, j + 14, k + 18, Block.stone.blockID);
		world.setBlock(i + 0, j + 14, k + 19, Block.stone.blockID);
		world.setBlock(i + 0, j + 14, k + 20, Block.stone.blockID);
		world.setBlock(i + 0, j + 14, k + 21, Block.stone.blockID);
		world.setBlock(i + 0, j + 14, k + 22, Block.stone.blockID);
		world.setBlock(i + 0, j + 14, k + 23, Block.stone.blockID);
		world.setBlock(i + 0, j + 14, k + 24, Block.stone.blockID);
		world.setBlock(i + 0, j + 14, k + 25, Block.stone.blockID);
		world.setBlock(i + 0, j + 14, k + 26, Block.stone.blockID);
		world.setBlock(i + 0, j + 14, k + 27, Block.stone.blockID);
		world.setBlock(i + 0, j + 14, k + 28, Block.stone.blockID);
		world.setBlock(i + 0, j + 14, k + 29, Block.stone.blockID);
		world.setBlock(i + 0, j + 14, k + 30, Block.stone.blockID);
		world.setBlock(i + 0, j + 14, k + 31, Block.stone.blockID);
		world.setBlock(i + 0, j + 14, k + 32, Block.stone.blockID);
		world.setBlock(i + 0, j + 14, k + 33, Block.stone.blockID);
		world.setBlock(i + 0, j + 14, k + 34, Block.stone.blockID);
		world.setBlock(i + 0, j + 15, k + 0, Block.stone.blockID);
		world.setBlock(i + 0, j + 15, k + 1, Block.stone.blockID);
		world.setBlock(i + 0, j + 15, k + 2, Block.stone.blockID);
		world.setBlock(i + 0, j + 15, k + 3, Block.stone.blockID);
		world.setBlock(i + 0, j + 15, k + 4, Block.stone.blockID);
		world.setBlock(i + 0, j + 15, k + 5, Block.stone.blockID);
		world.setBlock(i + 0, j + 15, k + 6, Block.stone.blockID);
		world.setBlock(i + 0, j + 15, k + 7, Block.stone.blockID);
		world.setBlock(i + 0, j + 15, k + 8, Block.stone.blockID);
		world.setBlock(i + 0, j + 15, k + 9, Block.stone.blockID);
		world.setBlock(i + 0, j + 15, k + 10, Block.stone.blockID);
		world.setBlock(i + 0, j + 15, k + 11, Block.stone.blockID);
		world.setBlock(i + 0, j + 15, k + 12, Block.stone.blockID);
		world.setBlock(i + 0, j + 15, k + 13, Block.stone.blockID);
		world.setBlock(i + 0, j + 15, k + 14, Block.stone.blockID);
		world.setBlock(i + 0, j + 15, k + 15, Block.stone.blockID);
		world.setBlock(i + 0, j + 15, k + 16, Block.stone.blockID);
		world.setBlock(i + 0, j + 15, k + 17, Block.stone.blockID);
		world.setBlock(i + 0, j + 15, k + 18, Block.stone.blockID);
		world.setBlock(i + 0, j + 15, k + 19, Block.stone.blockID);
		world.setBlock(i + 0, j + 15, k + 20, Block.stone.blockID);
		world.setBlock(i + 0, j + 15, k + 21, Block.stone.blockID);
		world.setBlock(i + 0, j + 15, k + 22, Block.stone.blockID);
		world.setBlock(i + 0, j + 15, k + 23, Block.stone.blockID);
		world.setBlock(i + 0, j + 15, k + 24, Block.stone.blockID);
		world.setBlock(i + 0, j + 15, k + 25, Block.stone.blockID);
		world.setBlock(i + 0, j + 15, k + 26, Block.stone.blockID);
		world.setBlock(i + 0, j + 15, k + 27, Block.stone.blockID);
		world.setBlock(i + 0, j + 15, k + 28, Block.stone.blockID);
		world.setBlock(i + 0, j + 15, k + 29, Block.stone.blockID);
		world.setBlock(i + 0, j + 15, k + 30, Block.stone.blockID);
		world.setBlock(i + 0, j + 15, k + 31, Block.stone.blockID);
		world.setBlock(i + 0, j + 15, k + 32, Block.stone.blockID);
		world.setBlock(i + 0, j + 15, k + 33, Block.stone.blockID);
		world.setBlock(i + 0, j + 15, k + 34, Block.stone.blockID);
		world.setBlock(i + 0, j + 16, k + 0, Block.stone.blockID);
		world.setBlock(i + 0, j + 16, k + 1, Block.stone.blockID);
		world.setBlock(i + 0, j + 16, k + 2, Block.stone.blockID);
		world.setBlock(i + 0, j + 16, k + 3, Block.stone.blockID);
		world.setBlock(i + 0, j + 16, k + 4, Block.stone.blockID);
		world.setBlock(i + 0, j + 16, k + 5, Block.stone.blockID);
		world.setBlock(i + 0, j + 16, k + 6, Block.stone.blockID);
		world.setBlock(i + 0, j + 16, k + 7, Block.stone.blockID);
		world.setBlock(i + 0, j + 16, k + 8, Block.stone.blockID);
		world.setBlock(i + 0, j + 16, k + 9, Block.stone.blockID);
		world.setBlock(i + 0, j + 16, k + 10, Block.stone.blockID);
		world.setBlock(i + 0, j + 16, k + 11, Block.stone.blockID);
		world.setBlock(i + 0, j + 16, k + 12, Block.stone.blockID);
		world.setBlock(i + 0, j + 16, k + 13, Block.stone.blockID);
		world.setBlock(i + 0, j + 16, k + 14, Block.stone.blockID);
		world.setBlock(i + 0, j + 16, k + 15, Block.stone.blockID);
		world.setBlock(i + 0, j + 16, k + 16, Block.stone.blockID);
		world.setBlock(i + 0, j + 16, k + 17, Block.stone.blockID);
		world.setBlock(i + 0, j + 16, k + 18, Block.stone.blockID);
		world.setBlock(i + 0, j + 16, k + 19, Block.stone.blockID);
		world.setBlock(i + 0, j + 16, k + 20, Block.stone.blockID);
		world.setBlock(i + 0, j + 16, k + 21, Block.stone.blockID);
		world.setBlock(i + 0, j + 16, k + 22, Block.stone.blockID);
		world.setBlock(i + 0, j + 16, k + 23, Block.stone.blockID);
		world.setBlock(i + 0, j + 16, k + 24, Block.stone.blockID);
		world.setBlock(i + 0, j + 16, k + 25, Block.stone.blockID);
		world.setBlock(i + 0, j + 16, k + 26, Block.stone.blockID);
		world.setBlock(i + 0, j + 16, k + 27, Block.stone.blockID);
		world.setBlock(i + 0, j + 16, k + 28, Block.stone.blockID);
		world.setBlock(i + 0, j + 16, k + 29, Block.stone.blockID);
		world.setBlock(i + 0, j + 16, k + 30, Block.stone.blockID);
		world.setBlock(i + 0, j + 16, k + 31, Block.stone.blockID);
		world.setBlock(i + 0, j + 16, k + 32, Block.stone.blockID);
		world.setBlock(i + 0, j + 16, k + 33, Block.stone.blockID);
		world.setBlock(i + 0, j + 16, k + 34, Block.stone.blockID);
		world.setBlock(i + 0, j + 17, k + 0, Block.stone.blockID);
		world.setBlock(i + 0, j + 17, k + 1, Block.stone.blockID);
		world.setBlock(i + 0, j + 17, k + 2, Block.stone.blockID);
		world.setBlock(i + 0, j + 17, k + 3, Block.stone.blockID);
		world.setBlock(i + 0, j + 17, k + 4, Block.stone.blockID);
		world.setBlock(i + 0, j + 17, k + 5, Block.stone.blockID);
		world.setBlock(i + 0, j + 17, k + 6, Block.stone.blockID);
		world.setBlock(i + 0, j + 17, k + 7, Block.stone.blockID);
		world.setBlock(i + 0, j + 17, k + 8, Block.stone.blockID);
		world.setBlock(i + 0, j + 17, k + 9, Block.stone.blockID);
		world.setBlock(i + 0, j + 17, k + 10, Block.stone.blockID);
		world.setBlock(i + 0, j + 17, k + 11, Block.stone.blockID);
		world.setBlock(i + 0, j + 17, k + 12, Block.stone.blockID);
		world.setBlock(i + 0, j + 17, k + 13, Block.stone.blockID);
		world.setBlock(i + 0, j + 17, k + 14, Block.stone.blockID);
		world.setBlock(i + 0, j + 17, k + 15, Block.stone.blockID);
		world.setBlock(i + 0, j + 17, k + 16, Block.stone.blockID);
		world.setBlock(i + 0, j + 17, k + 17, Block.stone.blockID);
		world.setBlock(i + 0, j + 17, k + 18, Block.stone.blockID);
		world.setBlock(i + 0, j + 17, k + 19, Block.stone.blockID);
		world.setBlock(i + 0, j + 17, k + 20, Block.stone.blockID);
		world.setBlock(i + 0, j + 17, k + 21, Block.stone.blockID);
		world.setBlock(i + 0, j + 17, k + 22, Block.stone.blockID);
		world.setBlock(i + 0, j + 17, k + 23, Block.stone.blockID);
		world.setBlock(i + 0, j + 17, k + 24, Block.stone.blockID);
		world.setBlock(i + 0, j + 17, k + 25, Block.stone.blockID);
		world.setBlock(i + 0, j + 17, k + 26, Block.stone.blockID);
		world.setBlock(i + 0, j + 17, k + 27, Block.stone.blockID);
		world.setBlock(i + 0, j + 17, k + 28, Block.stone.blockID);
		world.setBlock(i + 0, j + 17, k + 29, Block.stone.blockID);
		world.setBlock(i + 0, j + 17, k + 30, Block.stone.blockID);
		world.setBlock(i + 0, j + 17, k + 31, Block.stone.blockID);
		world.setBlock(i + 0, j + 17, k + 32, Block.stone.blockID);
		world.setBlock(i + 0, j + 17, k + 33, Block.stone.blockID);
		world.setBlock(i + 0, j + 17, k + 34, Block.stone.blockID);
		world.setBlock(i + 0, j + 18, k + 0, Block.stone.blockID);
		world.setBlock(i + 0, j + 18, k + 1, Block.stone.blockID);
		world.setBlock(i + 0, j + 18, k + 2, Block.stone.blockID);
		world.setBlock(i + 0, j + 18, k + 3, Block.stone.blockID);
		world.setBlock(i + 0, j + 18, k + 4, Block.stone.blockID);
		world.setBlock(i + 0, j + 18, k + 5, Block.stone.blockID);
		world.setBlock(i + 0, j + 18, k + 6, Block.stone.blockID);
		world.setBlock(i + 0, j + 18, k + 7, Block.stone.blockID);
		world.setBlock(i + 0, j + 18, k + 8, Block.stone.blockID);
		world.setBlock(i + 0, j + 18, k + 9, Block.stone.blockID);
		world.setBlock(i + 0, j + 18, k + 10, Block.stone.blockID);
		world.setBlock(i + 0, j + 18, k + 11, Block.stone.blockID);
		world.setBlock(i + 0, j + 18, k + 12, Block.stone.blockID);
		world.setBlock(i + 0, j + 18, k + 13, Block.stone.blockID);
		world.setBlock(i + 0, j + 18, k + 14, Block.stone.blockID);
		world.setBlock(i + 0, j + 18, k + 15, Block.stone.blockID);
		world.setBlock(i + 0, j + 18, k + 16, Block.stone.blockID);
		world.setBlock(i + 0, j + 18, k + 17, Block.stone.blockID);
		world.setBlock(i + 0, j + 18, k + 18, Block.stone.blockID);
		world.setBlock(i + 0, j + 18, k + 19, Block.stone.blockID);
		world.setBlock(i + 0, j + 18, k + 20, Block.stone.blockID);
		world.setBlock(i + 0, j + 18, k + 21, Block.stone.blockID);
		world.setBlock(i + 0, j + 18, k + 22, Block.stone.blockID);
		world.setBlock(i + 0, j + 18, k + 23, Block.stone.blockID);
		world.setBlock(i + 0, j + 18, k + 24, Block.stone.blockID);
		world.setBlock(i + 0, j + 18, k + 25, Block.stone.blockID);
		world.setBlock(i + 0, j + 18, k + 26, Block.stone.blockID);
		world.setBlock(i + 0, j + 18, k + 27, Block.stone.blockID);
		world.setBlock(i + 0, j + 18, k + 28, Block.stone.blockID);
		world.setBlock(i + 0, j + 18, k + 29, Block.stone.blockID);
		world.setBlock(i + 0, j + 18, k + 30, Block.stone.blockID);
		world.setBlock(i + 0, j + 18, k + 31, Block.stone.blockID);
		world.setBlock(i + 0, j + 18, k + 32, Block.stone.blockID);
		world.setBlock(i + 0, j + 18, k + 33, Block.stone.blockID);
		world.setBlock(i + 0, j + 18, k + 34, Block.stone.blockID);
		world.setBlock(i + 0, j + 19, k + 0, Block.stone.blockID);
		world.setBlock(i + 0, j + 19, k + 1, Block.stone.blockID);
		world.setBlock(i + 0, j + 19, k + 2, Block.stone.blockID);
		world.setBlock(i + 0, j + 19, k + 3, Block.stone.blockID);
		world.setBlock(i + 0, j + 19, k + 4, Block.stone.blockID);
		world.setBlock(i + 0, j + 19, k + 5, Block.stone.blockID);
		world.setBlock(i + 0, j + 19, k + 6, Block.stone.blockID);
		world.setBlock(i + 0, j + 19, k + 7, Block.stone.blockID);
		world.setBlock(i + 0, j + 19, k + 8, Block.stone.blockID);
		world.setBlock(i + 0, j + 19, k + 9, Block.stone.blockID);
		world.setBlock(i + 0, j + 19, k + 10, Block.stone.blockID);
		world.setBlock(i + 0, j + 19, k + 11, Block.stone.blockID);
		world.setBlock(i + 0, j + 19, k + 12, Block.stone.blockID);
		world.setBlock(i + 0, j + 19, k + 13, Block.stone.blockID);
		world.setBlock(i + 0, j + 19, k + 14, Block.stone.blockID);
		world.setBlock(i + 0, j + 19, k + 15, Block.stone.blockID);
		world.setBlock(i + 0, j + 19, k + 16, Block.stone.blockID);
		world.setBlock(i + 0, j + 19, k + 17, Block.stone.blockID);
		world.setBlock(i + 0, j + 19, k + 18, Block.stone.blockID);
		world.setBlock(i + 0, j + 19, k + 19, Block.stone.blockID);
		world.setBlock(i + 0, j + 19, k + 20, Block.stone.blockID);
		world.setBlock(i + 0, j + 19, k + 21, Block.stone.blockID);
		world.setBlock(i + 0, j + 19, k + 22, Block.stone.blockID);
		world.setBlock(i + 0, j + 19, k + 23, Block.stone.blockID);
		world.setBlock(i + 0, j + 19, k + 24, Block.stone.blockID);
		world.setBlock(i + 0, j + 19, k + 25, Block.stone.blockID);
		world.setBlock(i + 0, j + 19, k + 26, Block.stone.blockID);
		world.setBlock(i + 0, j + 19, k + 27, Block.stone.blockID);
		world.setBlock(i + 0, j + 19, k + 28, Block.stone.blockID);
		world.setBlock(i + 0, j + 19, k + 29, Block.stone.blockID);
		world.setBlock(i + 0, j + 19, k + 30, Block.stone.blockID);
		world.setBlock(i + 0, j + 19, k + 31, Block.stone.blockID);
		world.setBlock(i + 0, j + 19, k + 32, Block.stone.blockID);
		world.setBlock(i + 0, j + 19, k + 33, Block.stone.blockID);
		world.setBlock(i + 0, j + 19, k + 34, Block.stone.blockID);
		world.setBlock(i + 1, j + 0, k + 0, Block.stone.blockID);
		world.setBlock(i + 1, j + 0, k + 1, Block.stone.blockID);
		world.setBlock(i + 1, j + 0, k + 2, Block.stone.blockID);
		world.setBlock(i + 1, j + 0, k + 3, Block.stone.blockID);
		world.setBlock(i + 1, j + 0, k + 4, Block.stone.blockID);
		world.setBlock(i + 1, j + 0, k + 5, Block.stone.blockID);
		world.setBlock(i + 1, j + 0, k + 6, Block.stone.blockID);
		world.setBlock(i + 1, j + 0, k + 7, Block.stone.blockID);
		world.setBlock(i + 1, j + 0, k + 8, Block.stone.blockID);
		world.setBlock(i + 1, j + 0, k + 9, Block.stone.blockID);
		world.setBlock(i + 1, j + 0, k + 10, Block.stone.blockID);
		world.setBlock(i + 1, j + 0, k + 11, Block.stone.blockID);
		world.setBlock(i + 1, j + 0, k + 12, Block.stone.blockID);
		world.setBlock(i + 1, j + 0, k + 13, Block.stone.blockID);
		world.setBlock(i + 1, j + 0, k + 14, Block.stone.blockID);
		world.setBlock(i + 1, j + 0, k + 15, Block.stone.blockID);
		world.setBlock(i + 1, j + 0, k + 16, Block.stone.blockID);
		world.setBlock(i + 1, j + 0, k + 17, Block.stone.blockID);
		world.setBlock(i + 1, j + 0, k + 18, Block.stone.blockID);
		world.setBlock(i + 1, j + 0, k + 19, Block.stone.blockID);
		world.setBlock(i + 1, j + 0, k + 20, Block.stone.blockID);
		world.setBlock(i + 1, j + 0, k + 21, Block.stone.blockID);
		world.setBlock(i + 1, j + 0, k + 22, Block.stone.blockID);
		world.setBlock(i + 1, j + 0, k + 23, Block.stone.blockID);
		world.setBlock(i + 1, j + 0, k + 24, Block.stone.blockID);
		world.setBlock(i + 1, j + 0, k + 25, Block.stone.blockID);
		world.setBlock(i + 1, j + 0, k + 26, Block.stone.blockID);
		world.setBlock(i + 1, j + 0, k + 27, Block.stone.blockID);
		world.setBlock(i + 1, j + 0, k + 28, Block.stone.blockID);
		world.setBlock(i + 1, j + 0, k + 29, Block.stone.blockID);
		world.setBlock(i + 1, j + 0, k + 30, Block.stone.blockID);
		world.setBlock(i + 1, j + 0, k + 31, Block.stone.blockID);
		world.setBlock(i + 1, j + 0, k + 32, Block.stone.blockID);
		world.setBlock(i + 1, j + 0, k + 33, Block.stone.blockID);
		world.setBlock(i + 1, j + 0, k + 34, Block.stone.blockID);
		world.setBlock(i + 1, j + 1, k + 0, Block.stone.blockID);
		world.setBlock(i + 1, j + 1, k + 1, Block.stoneBrick.blockID);
		world.setBlock(i + 1, j + 1, k + 2, Block.stoneBrick.blockID);
		world.setBlock(i + 1, j + 1, k + 3, Block.stoneBrick.blockID);
		world.setBlock(i + 1, j + 1, k + 4, Block.stoneBrick.blockID);
		world.setBlock(i + 1, j + 1, k + 5, Block.stoneBrick.blockID);
		world.setBlock(i + 1, j + 1, k + 6, Block.stoneBrick.blockID);
		world.setBlock(i + 1, j + 1, k + 7, Block.stoneBrick.blockID);
		world.setBlock(i + 1, j + 1, k + 8, Block.stoneBrick.blockID);
		world.setBlock(i + 1, j + 1, k + 9, Block.stoneBrick.blockID);
		world.setBlock(i + 1, j + 1, k + 10, Block.stoneBrick.blockID);
		world.setBlock(i + 1, j + 1, k + 11, Block.stoneBrick.blockID);
		world.setBlock(i + 1, j + 1, k + 12, Block.stoneBrick.blockID);
		world.setBlock(i + 1, j + 1, k + 13, Block.stoneBrick.blockID);
		world.setBlock(i + 1, j + 1, k + 14, Block.stoneBrick.blockID);
		world.setBlock(i + 1, j + 1, k + 15, Block.stoneBrick.blockID);
		world.setBlock(i + 1, j + 1, k + 16, Block.stoneBrick.blockID);
		world.setBlock(i + 1, j + 1, k + 17, Block.stoneBrick.blockID);
		world.setBlock(i + 1, j + 1, k + 18, Block.stoneBrick.blockID);
		world.setBlock(i + 1, j + 1, k + 19, Block.stoneBrick.blockID);
		world.setBlock(i + 1, j + 1, k + 20, Block.stoneBrick.blockID);
		world.setBlock(i + 1, j + 1, k + 21, Block.stoneBrick.blockID);
		world.setBlock(i + 1, j + 1, k + 22, Block.stoneBrick.blockID);
		world.setBlock(i + 1, j + 1, k + 23, Block.stoneBrick.blockID);
		world.setBlock(i + 1, j + 1, k + 24, Block.stoneBrick.blockID);
		world.setBlock(i + 1, j + 1, k + 25, Block.stone.blockID);
		world.setBlock(i + 1, j + 1, k + 26, Block.stone.blockID);
		world.setBlock(i + 1, j + 1, k + 27, Block.stone.blockID);
		world.setBlock(i + 1, j + 1, k + 28, Block.stone.blockID);
		world.setBlock(i + 1, j + 1, k + 29, Block.stone.blockID);
		world.setBlock(i + 1, j + 1, k + 30, Block.stone.blockID);
		world.setBlock(i + 1, j + 1, k + 31, Block.stone.blockID);
		world.setBlock(i + 1, j + 1, k + 32, Block.stone.blockID);
		world.setBlock(i + 1, j + 1, k + 33, Block.stone.blockID);
		world.setBlock(i + 1, j + 1, k + 34, Block.stone.blockID);
		world.setBlock(i + 1, j + 2, k + 0, Block.stone.blockID);
		world.setBlock(i + 1, j + 2, k + 1, Block.stone.blockID);
		world.setBlock(i + 1, j + 2, k + 2, Block.stoneBrick.blockID);
		world.setBlock(i + 1, j + 2, k + 3, Block.stoneBrick.blockID);
		world.setBlock(i + 1, j + 2, k + 4, Block.stoneBrick.blockID);
		world.setBlock(i + 1, j + 2, k + 5, Block.stoneBrick.blockID);
		world.setBlock(i + 1, j + 2, k + 6, Block.stoneBrick.blockID);
		world.setBlock(i + 1, j + 2, k + 7, Block.stoneBrick.blockID);
		world.setBlock(i + 1, j + 2, k + 8, Block.stoneBrick.blockID);
		world.setBlock(i + 1, j + 2, k + 9, Block.stoneBrick.blockID);
		world.setBlock(i + 1, j + 2, k + 10, Block.stoneBrick.blockID);
		world.setBlock(i + 1, j + 2, k + 11, Block.stoneBrick.blockID);
		world.setBlock(i + 1, j + 2, k + 12, Block.stoneBrick.blockID);
		world.setBlock(i + 1, j + 2, k + 13, Block.stoneBrick.blockID);
		world.setBlock(i + 1, j + 2, k + 14, Block.stoneBrick.blockID);
		world.setBlock(i + 1, j + 2, k + 15, Block.stoneBrick.blockID);
		world.setBlock(i + 1, j + 2, k + 16, Block.stoneBrick.blockID);
		world.setBlock(i + 1, j + 2, k + 17, Block.stoneBrick.blockID);
		world.setBlock(i + 1, j + 2, k + 18, Block.stoneBrick.blockID);
		world.setBlock(i + 1, j + 2, k + 19, Block.stoneBrick.blockID);
		world.setBlock(i + 1, j + 2, k + 20, Block.stoneBrick.blockID);
		world.setBlock(i + 1, j + 2, k + 21, Block.stoneBrick.blockID);
		world.setBlock(i + 1, j + 2, k + 22, Block.stoneBrick.blockID);
		world.setBlock(i + 1, j + 2, k + 23, Block.stoneBrick.blockID);
		world.setBlock(i + 1, j + 2, k + 24, Block.stoneBrick.blockID);
		world.setBlock(i + 1, j + 2, k + 25, Block.stone.blockID);
		world.setBlock(i + 1, j + 2, k + 26, Block.stoneBrick.blockID);
		world.setBlock(i + 1, j + 2, k + 27, Block.stoneBrick.blockID);
		world.setBlock(i + 1, j + 2, k + 28, Block.stoneBrick.blockID);
		world.setBlock(i + 1, j + 2, k + 31, Block.stone.blockID);
		world.setBlock(i + 1, j + 2, k + 32, Block.stone.blockID);
		world.setBlock(i + 1, j + 2, k + 33, Block.stone.blockID);
		world.setBlock(i + 1, j + 2, k + 34, Block.stone.blockID);
		world.setBlock(i + 1, j + 3, k + 0, Block.stone.blockID);
		world.setBlock(i + 1, j + 3, k + 1, Block.stone.blockID);
		world.setBlock(i + 1, j + 3, k + 2, Block.stone.blockID);
		world.setBlock(i + 1, j + 3, k + 16, Block.stone.blockID);
		world.setBlock(i + 1, j + 3, k + 17, Block.stone.blockID);
		world.setBlock(i + 1, j + 3, k + 18, Block.stone.blockID);
		world.setBlock(i + 1, j + 3, k + 22, Block.stone.blockID);
		world.setBlock(i + 1, j + 3, k + 24, Block.stoneBrick.blockID);
		world.setBlock(i + 1, j + 3, k + 25, Block.stone.blockID);
		world.setBlock(i + 1, j + 3, k + 26, Block.stone.blockID);
		world.setBlock(i + 1, j + 3, k + 27, Block.stone.blockID);
		world.setBlock(i + 1, j + 3, k + 28, Block.stoneBrick.blockID);
		world.setBlock(i + 1, j + 3, k + 29, Block.stoneBrick.blockID);
		world.setBlock(i + 1, j + 3, k + 30, Block.stone.blockID);
		world.setBlock(i + 1, j + 3, k + 31, Block.stone.blockID);
		world.setBlock(i + 1, j + 3, k + 32, Block.stone.blockID);
		world.setBlock(i + 1, j + 3, k + 33, Block.stone.blockID);
		world.setBlock(i + 1, j + 3, k + 34, Block.stone.blockID);
		world.setBlock(i + 1, j + 4, k + 0, Block.stone.blockID);
		world.setBlock(i + 1, j + 4, k + 1, Block.stone.blockID);
		world.setBlock(i + 1, j + 4, k + 2, Block.stone.blockID);
		world.setBlock(i + 1, j + 4, k + 16, Block.stone.blockID);
		world.setBlock(i + 1, j + 4, k + 17, Block.stone.blockID);
		world.setBlock(i + 1, j + 4, k + 18, Block.stone.blockID);
		world.setBlock(i + 1, j + 4, k + 19, Block.stone.blockID);
		world.setBlock(i + 1, j + 4, k + 21, Block.stone.blockID);
		world.setBlock(i + 1, j + 4, k + 22, Block.stone.blockID);
		world.setBlock(i + 1, j + 4, k + 23, Block.stone.blockID);
		world.setBlock(i + 1, j + 4, k + 24, Block.stoneBrick.blockID);
		world.setBlock(i + 1, j + 4, k + 25, Block.stone.blockID);
		world.setBlock(i + 1, j + 4, k + 26, Block.stone.blockID);
		world.setBlock(i + 1, j + 4, k + 27, Block.stone.blockID);
		world.setBlock(i + 1, j + 4, k + 28, Block.stoneBrick.blockID);
		world.setBlock(i + 1, j + 4, k + 29, Block.stoneBrick.blockID);
		world.setBlock(i + 1, j + 4, k + 31, Block.stone.blockID);
		world.setBlock(i + 1, j + 4, k + 32, Block.stone.blockID);
		world.setBlock(i + 1, j + 4, k + 33, Block.stone.blockID);
		world.setBlock(i + 1, j + 4, k + 34, Block.stone.blockID);
		world.setBlock(i + 1, j + 5, k + 0, Block.stone.blockID);
		world.setBlock(i + 1, j + 5, k + 1, Block.stone.blockID);
		world.setBlock(i + 1, j + 5, k + 2, Block.stone.blockID);
		world.setBlock(i + 1, j + 5, k + 16, Block.stone.blockID);
		world.setBlock(i + 1, j + 5, k + 17, Block.stone.blockID);
		world.setBlock(i + 1, j + 5, k + 18, Block.stone.blockID);
		world.setBlock(i + 1, j + 5, k + 19, Block.stone.blockID);
		world.setBlock(i + 1, j + 5, k + 22, Block.stone.blockID);
		world.setBlock(i + 1, j + 5, k + 24, Block.stoneBrick.blockID);
		world.setBlock(i + 1, j + 5, k + 25, Block.stone.blockID);
		world.setBlock(i + 1, j + 5, k + 26, Block.stone.blockID);
		world.setBlock(i + 1, j + 5, k + 28, Block.stoneBrick.blockID);
		world.setBlock(i + 1, j + 5, k + 29, Block.stoneBrick.blockID);
		world.setBlock(i + 1, j + 5, k + 30, Block.stoneBrick.blockID);
		world.setBlock(i + 1, j + 5, k + 31, Block.stone.blockID);
		world.setBlock(i + 1, j + 5, k + 32, Block.stone.blockID);
		world.setBlock(i + 1, j + 5, k + 33, Block.stone.blockID);
		world.setBlock(i + 1, j + 5, k + 34, Block.stone.blockID);
		world.setBlock(i + 1, j + 6, k + 0, Block.stone.blockID);
		world.setBlock(i + 1, j + 6, k + 1, Block.stone.blockID);
		world.setBlock(i + 1, j + 6, k + 2, Block.stone.blockID);
		world.setBlock(i + 1, j + 6, k + 14, Block.stone.blockID);
		world.setBlock(i + 1, j + 6, k + 18, Block.stone.blockID);
		world.setBlock(i + 1, j + 6, k + 19, Block.stone.blockID);
		world.setBlock(i + 1, j + 6, k + 24, Block.stoneBrick.blockID);
		world.setBlock(i + 1, j + 6, k + 25, Block.stone.blockID);
		world.setBlock(i + 1, j + 6, k + 26, Block.stone.blockID);
		world.setBlock(i + 1, j + 6, k + 28, Block.stoneBrick.blockID);
		world.setBlock(i + 1, j + 6, k + 29, Block.stoneBrick.blockID);
		world.setBlock(i + 1, j + 6, k + 30, Block.stoneBrick.blockID);
		world.setBlock(i + 1, j + 6, k + 31, Block.stone.blockID);
		world.setBlock(i + 1, j + 6, k + 32, Block.stone.blockID);
		world.setBlock(i + 1, j + 6, k + 33, Block.stone.blockID);
		world.setBlock(i + 1, j + 6, k + 34, Block.stone.blockID);
		world.setBlock(i + 1, j + 7, k + 0, Block.stone.blockID);
		world.setBlock(i + 1, j + 7, k + 1, Block.stone.blockID);
		world.setBlock(i + 1, j + 7, k + 2, Block.stone.blockID);
		world.setBlock(i + 1, j + 7, k + 11, Block.stone.blockID);
		world.setBlock(i + 1, j + 7, k + 13, Block.stone.blockID);
		world.setBlock(i + 1, j + 7, k + 14, Block.stone.blockID);
		world.setBlock(i + 1, j + 7, k + 15, Block.stone.blockID);
		world.setBlock(i + 1, j + 7, k + 17, Block.stone.blockID);
		world.setBlock(i + 1, j + 7, k + 18, Block.stone.blockID);
		world.setBlock(i + 1, j + 7, k + 19, Block.stone.blockID);
		world.setBlock(i + 1, j + 7, k + 20, Block.stone.blockID);
		world.setBlockMetadataWithNotify(i + 1, j + 7, k + 23, Block.stoneSingleSlab.blockID, 8);
		world.setBlock(i + 1, j + 7, k + 24, Block.stoneBrick.blockID);
		world.setBlock(i + 1, j + 7, k + 25, Block.stone.blockID);
		world.setBlock(i + 1, j + 7, k + 28, Block.stone.blockID);
		world.setBlock(i + 1, j + 7, k + 29, Block.stone.blockID);
		world.setBlock(i + 1, j + 7, k + 30, Block.stone.blockID);
		world.setBlock(i + 1, j + 7, k + 31, Block.stone.blockID);
		world.setBlock(i + 1, j + 7, k + 32, Block.stone.blockID);
		world.setBlock(i + 1, j + 7, k + 33, Block.stone.blockID);
		world.setBlock(i + 1, j + 7, k + 34, Block.stone.blockID);
		world.setBlock(i + 1, j + 8, k + 0, Block.stone.blockID);
		world.setBlock(i + 1, j + 8, k + 1, Block.stone.blockID);
		world.setBlock(i + 1, j + 8, k + 2, Block.stone.blockID);
		world.setBlock(i + 1, j + 8, k + 3, Block.stone.blockID);
		world.setBlock(i + 1, j + 8, k + 10, Block.stone.blockID);
		world.setBlock(i + 1, j + 8, k + 11, Block.stone.blockID);
		world.setBlock(i + 1, j + 8, k + 12, Block.stone.blockID);
		world.setBlock(i + 1, j + 8, k + 13, Block.stone.blockID);
		world.setBlock(i + 1, j + 8, k + 14, Block.stone.blockID);
		world.setBlock(i + 1, j + 8, k + 16, Block.stone.blockID);
		world.setBlock(i + 1, j + 8, k + 17, Block.stone.blockID);
		world.setBlock(i + 1, j + 8, k + 18, Block.stone.blockID);
		world.setBlock(i + 1, j + 8, k + 19, Block.stone.blockID);
		world.setBlock(i + 1, j + 8, k + 25, Block.stone.blockID);
		world.setBlockMetadataWithNotify(i + 1, j + 8, k + 32, Block.stoneBrick.blockID, 2);
		world.setBlock(i + 1, j + 8, k + 33, Block.stone.blockID);
		world.setBlock(i + 1, j + 8, k + 34, Block.stone.blockID);
		world.setBlock(i + 1, j + 9, k + 0, Block.stone.blockID);
		world.setBlock(i + 1, j + 9, k + 1, Block.stone.blockID);
		world.setBlock(i + 1, j + 9, k + 2, Block.stone.blockID);
		world.setBlock(i + 1, j + 9, k + 3, Block.stone.blockID);
		world.setBlock(i + 1, j + 9, k + 11, Block.stone.blockID);
		world.setBlock(i + 1, j + 9, k + 12, Block.stone.blockID);
		world.setBlock(i + 1, j + 9, k + 13, Block.stone.blockID);
		world.setBlock(i + 1, j + 9, k + 14, Block.stone.blockID);
		world.setBlock(i + 1, j + 9, k + 16, Block.stone.blockID);
		world.setBlock(i + 1, j + 9, k + 17, Block.stone.blockID);
		world.setBlock(i + 1, j + 9, k + 25, Block.stone.blockID);
		world.setBlockMetadataWithNotify(i + 1, j + 9, k + 32, Block.stoneBrick.blockID, 2);
		world.setBlock(i + 1, j + 9, k + 33, Block.stone.blockID);
		world.setBlock(i + 1, j + 9, k + 34, Block.stone.blockID);
		world.setBlock(i + 1, j + 10, k + 0, Block.stone.blockID);
		world.setBlock(i + 1, j + 10, k + 1, Block.stone.blockID);
		world.setBlock(i + 1, j + 10, k + 2, Block.stone.blockID);
		world.setBlock(i + 1, j + 10, k + 3, Block.stone.blockID);
		world.setBlock(i + 1, j + 10, k + 11, Block.stone.blockID);
		world.setBlock(i + 1, j + 10, k + 12, Block.stone.blockID);
		world.setBlock(i + 1, j + 10, k + 13, Block.stone.blockID);
		world.setBlock(i + 1, j + 10, k + 15, Block.stone.blockID);
		world.setBlock(i + 1, j + 10, k + 16, Block.stone.blockID);
		world.setBlock(i + 1, j + 10, k + 17, Block.stone.blockID);
		world.setBlock(i + 1, j + 10, k + 25, Block.stone.blockID);
		world.setBlock(i + 1, j + 10, k + 33, Block.stone.blockID);
		world.setBlock(i + 1, j + 10, k + 34, Block.stone.blockID);
		world.setBlock(i + 1, j + 11, k + 0, Block.stone.blockID);
		world.setBlock(i + 1, j + 11, k + 1, Block.stone.blockID);
		world.setBlock(i + 1, j + 11, k + 2, Block.stone.blockID);
		world.setBlock(i + 1, j + 11, k + 3, Block.stone.blockID);
		world.setBlock(i + 1, j + 11, k + 4, Block.stone.blockID);
		world.setBlock(i + 1, j + 11, k + 10, Block.stone.blockID);
		world.setBlock(i + 1, j + 11, k + 11, Block.stone.blockID);
		world.setBlock(i + 1, j + 11, k + 12, Block.stone.blockID);
		world.setBlock(i + 1, j + 11, k + 16, Block.stone.blockID);
		world.setBlock(i + 1, j + 11, k + 19, Block.stone.blockID);
		world.setBlock(i + 1, j + 11, k + 25, Block.stone.blockID);
		world.setBlock(i + 1, j + 11, k + 33, Block.stoneBrick.blockID);
		world.setBlock(i + 1, j + 11, k + 34, Block.stone.blockID);
		world.setBlock(i + 1, j + 12, k + 0, Block.stone.blockID);
		world.setBlock(i + 1, j + 12, k + 1, Block.stone.blockID);
		world.setBlock(i + 1, j + 12, k + 2, Block.stone.blockID);
		world.setBlock(i + 1, j + 12, k + 3, Block.stone.blockID);
		world.setBlock(i + 1, j + 12, k + 4, Block.stone.blockID);
		world.setBlock(i + 1, j + 12, k + 11, Block.stone.blockID);
		world.setBlock(i + 1, j + 12, k + 18, Block.stone.blockID);
		world.setBlock(i + 1, j + 12, k + 19, Block.stone.blockID);
		world.setBlock(i + 1, j + 12, k + 20, Block.stone.blockID);
		world.setBlock(i + 1, j + 12, k + 22, Block.stone.blockID);
		world.setBlock(i + 1, j + 12, k + 23, Block.stone.blockID);
		world.setBlock(i + 1, j + 12, k + 24, Block.stone.blockID);
		world.setBlock(i + 1, j + 12, k + 25, Block.stone.blockID);
		world.setBlock(i + 1, j + 12, k + 26, Block.stone.blockID);
		world.setBlock(i + 1, j + 12, k + 27, Block.stone.blockID);
		world.setBlock(i + 1, j + 12, k + 28, Block.stone.blockID);
		world.setBlock(i + 1, j + 12, k + 31, Block.stone.blockID);
		world.setBlock(i + 1, j + 12, k + 32, Block.stone.blockID);
		world.setBlock(i + 1, j + 12, k + 33, Block.stoneBrick.blockID);
		world.setBlock(i + 1, j + 12, k + 34, Block.stone.blockID);
		world.setBlock(i + 1, j + 13, k + 0, Block.stone.blockID);
		world.setBlock(i + 1, j + 13, k + 1, Block.stone.blockID);
		world.setBlock(i + 1, j + 13, k + 2, Block.stone.blockID);
		world.setBlock(i + 1, j + 13, k + 3, Block.stone.blockID);
		world.setBlock(i + 1, j + 13, k + 4, Block.stone.blockID);
		world.setBlock(i + 1, j + 13, k + 5, Block.stone.blockID);
		world.setBlock(i + 1, j + 13, k + 19, Block.stone.blockID);
		world.setBlock(i + 1, j + 13, k + 22, Block.stone.blockID);
		world.setBlock(i + 1, j + 13, k + 23, Block.stone.blockID);
		world.setBlock(i + 1, j + 13, k + 24, Block.stone.blockID);
		world.setBlock(i + 1, j + 13, k + 25, Block.stone.blockID);
		world.setBlock(i + 1, j + 13, k + 26, Block.stone.blockID);
		world.setBlock(i + 1, j + 13, k + 27, Block.stone.blockID);
		world.setBlock(i + 1, j + 13, k + 28, Block.stone.blockID);
		world.setBlock(i + 1, j + 13, k + 29, Block.stoneBrick.blockID);
		world.setBlock(i + 1, j + 13, k + 30, Block.stoneBrick.blockID);
		world.setBlock(i + 1, j + 13, k + 31, Block.stoneBrick.blockID);
		world.setBlock(i + 1, j + 13, k + 32, Block.stoneBrick.blockID);
		world.setBlock(i + 1, j + 13, k + 33, Block.stoneBrick.blockID);
		world.setBlock(i + 1, j + 13, k + 34, Block.stone.blockID);
		world.setBlock(i + 1, j + 14, k + 0, Block.stone.blockID);
		world.setBlock(i + 1, j + 14, k + 1, Block.stone.blockID);
		world.setBlock(i + 1, j + 14, k + 2, Block.stone.blockID);
		world.setBlock(i + 1, j + 14, k + 3, Block.stone.blockID);
		world.setBlock(i + 1, j + 14, k + 4, Block.stone.blockID);
		world.setBlock(i + 1, j + 14, k + 5, Block.stone.blockID);
		world.setBlock(i + 1, j + 14, k + 6, Block.stone.blockID);
		world.setBlock(i + 1, j + 14, k + 22, Block.stone.blockID);
		world.setBlock(i + 1, j + 14, k + 23, Block.stone.blockID);
		world.setBlock(i + 1, j + 14, k + 24, Block.stone.blockID);
		world.setBlock(i + 1, j + 14, k + 25, Block.stone.blockID);
		world.setBlock(i + 1, j + 14, k + 26, Block.stone.blockID);
		world.setBlock(i + 1, j + 14, k + 27, Block.stone.blockID);
		world.setBlock(i + 1, j + 14, k + 28, Block.stone.blockID);
		world.setBlock(i + 1, j + 14, k + 33, Block.stone.blockID);
		world.setBlock(i + 1, j + 14, k + 34, Block.stone.blockID);
		world.setBlock(i + 1, j + 15, k + 0, Block.stone.blockID);
		world.setBlock(i + 1, j + 15, k + 1, Block.stone.blockID);
		world.setBlock(i + 1, j + 15, k + 2, Block.stone.blockID);
		world.setBlock(i + 1, j + 15, k + 3, Block.stone.blockID);
		world.setBlock(i + 1, j + 15, k + 4, Block.stone.blockID);
		world.setBlock(i + 1, j + 15, k + 5, Block.stone.blockID);
		world.setBlock(i + 1, j + 15, k + 6, Block.stone.blockID);
		world.setBlock(i + 1, j + 15, k + 11, Block.stone.blockID);
		world.setBlock(i + 1, j + 15, k + 15, Block.stone.blockID);
		world.setBlock(i + 1, j + 15, k + 16, Block.stone.blockID);
		world.setBlock(i + 1, j + 15, k + 17, Block.stone.blockID);
		world.setBlock(i + 1, j + 15, k + 22, Block.stone.blockID);
		world.setBlock(i + 1, j + 15, k + 23, Block.stone.blockID);
		world.setBlock(i + 1, j + 15, k + 24, Block.stone.blockID);
		world.setBlock(i + 1, j + 15, k + 25, Block.stone.blockID);
		world.setBlock(i + 1, j + 15, k + 26, Block.stone.blockID);
		world.setBlock(i + 1, j + 15, k + 27, Block.stone.blockID);
		world.setBlock(i + 1, j + 15, k + 28, Block.stone.blockID);
		world.setBlock(i + 1, j + 15, k + 29, Block.stone.blockID);
		world.setBlock(i + 1, j + 15, k + 30, Block.stone.blockID);
		world.setBlock(i + 1, j + 15, k + 31, Block.stone.blockID);
		world.setBlock(i + 1, j + 15, k + 32, Block.stone.blockID);
		world.setBlock(i + 1, j + 15, k + 33, Block.stone.blockID);
		world.setBlock(i + 1, j + 15, k + 34, Block.stone.blockID);
		world.setBlock(i + 1, j + 16, k + 0, Block.stone.blockID);
		world.setBlock(i + 1, j + 16, k + 1, Block.stone.blockID);
		world.setBlock(i + 1, j + 16, k + 2, Block.stone.blockID);
		world.setBlock(i + 1, j + 16, k + 3, Block.stone.blockID);
		world.setBlock(i + 1, j + 16, k + 4, Block.stone.blockID);
		world.setBlock(i + 1, j + 16, k + 5, Block.stone.blockID);
		world.setBlock(i + 1, j + 16, k + 6, Block.stone.blockID);
		world.setBlock(i + 1, j + 16, k + 7, Block.stone.blockID);
		world.setBlock(i + 1, j + 16, k + 8, Block.stone.blockID);
		world.setBlock(i + 1, j + 16, k + 9, Block.stone.blockID);
		world.setBlock(i + 1, j + 16, k + 10, Block.stone.blockID);
		world.setBlock(i + 1, j + 16, k + 11, Block.stone.blockID);
		world.setBlock(i + 1, j + 16, k + 12, Block.stone.blockID);
		world.setBlock(i + 1, j + 16, k + 15, Block.stone.blockID);
		world.setBlock(i + 1, j + 16, k + 16, Block.stone.blockID);
		world.setBlock(i + 1, j + 16, k + 17, Block.stone.blockID);
		world.setBlock(i + 1, j + 16, k + 18, Block.stone.blockID);
		world.setBlock(i + 1, j + 16, k + 22, Block.stone.blockID);
		world.setBlock(i + 1, j + 16, k + 23, Block.stone.blockID);
		world.setBlock(i + 1, j + 16, k + 24, Block.stone.blockID);
		world.setBlock(i + 1, j + 16, k + 25, Block.stone.blockID);
		world.setBlock(i + 1, j + 16, k + 26, Block.stone.blockID);
		world.setBlock(i + 1, j + 16, k + 27, Block.stone.blockID);
		world.setBlock(i + 1, j + 16, k + 28, Block.stone.blockID);
		world.setBlock(i + 1, j + 16, k + 29, Block.stone.blockID);
		world.setBlock(i + 1, j + 16, k + 30, Block.stone.blockID);
		world.setBlock(i + 1, j + 16, k + 31, Block.stone.blockID);
		world.setBlock(i + 1, j + 16, k + 32, Block.stone.blockID);
		world.setBlock(i + 1, j + 16, k + 33, Block.stone.blockID);
		world.setBlock(i + 1, j + 16, k + 34, Block.stone.blockID);
		world.setBlock(i + 1, j + 17, k + 0, Block.stone.blockID);
		world.setBlock(i + 1, j + 17, k + 1, Block.stone.blockID);
		world.setBlock(i + 1, j + 17, k + 2, Block.stone.blockID);
		world.setBlock(i + 1, j + 17, k + 3, Block.stone.blockID);
		world.setBlock(i + 1, j + 17, k + 4, Block.stone.blockID);
		world.setBlock(i + 1, j + 17, k + 5, Block.stone.blockID);
		world.setBlock(i + 1, j + 17, k + 6, Block.stone.blockID);
		world.setBlock(i + 1, j + 17, k + 7, Block.stone.blockID);
		world.setBlock(i + 1, j + 17, k + 8, Block.stone.blockID);
		world.setBlock(i + 1, j + 17, k + 9, Block.stone.blockID);
		world.setBlock(i + 1, j + 17, k + 10, Block.stone.blockID);
		world.setBlock(i + 1, j + 17, k + 11, Block.stone.blockID);
		world.setBlock(i + 1, j + 17, k + 12, Block.stone.blockID);
		world.setBlock(i + 1, j + 17, k + 13, Block.stone.blockID);
		world.setBlock(i + 1, j + 17, k + 14, Block.stone.blockID);
		world.setBlock(i + 1, j + 17, k + 15, Block.stone.blockID);
		world.setBlock(i + 1, j + 17, k + 16, Block.stone.blockID);
		world.setBlock(i + 1, j + 17, k + 17, Block.stone.blockID);
		world.setBlock(i + 1, j + 17, k + 18, Block.stone.blockID);
		world.setBlock(i + 1, j + 17, k + 19, Block.stone.blockID);
		world.setBlock(i + 1, j + 17, k + 20, Block.stone.blockID);
		world.setBlock(i + 1, j + 17, k + 22, Block.stone.blockID);
		world.setBlock(i + 1, j + 17, k + 23, Block.stone.blockID);
		world.setBlock(i + 1, j + 17, k + 24, Block.stone.blockID);
		world.setBlock(i + 1, j + 17, k + 25, Block.stone.blockID);
		world.setBlock(i + 1, j + 17, k + 26, Block.stone.blockID);
		world.setBlock(i + 1, j + 17, k + 27, Block.stone.blockID);
		world.setBlock(i + 1, j + 17, k + 28, Block.stone.blockID);
		world.setBlock(i + 1, j + 17, k + 29, Block.stone.blockID);
		world.setBlock(i + 1, j + 17, k + 30, Block.stone.blockID);
		world.setBlock(i + 1, j + 17, k + 31, Block.stone.blockID);
		world.setBlock(i + 1, j + 17, k + 32, Block.stone.blockID);
		world.setBlock(i + 1, j + 17, k + 33, Block.stone.blockID);
		world.setBlock(i + 1, j + 17, k + 34, Block.stone.blockID);
		world.setBlock(i + 1, j + 18, k + 0, Block.stone.blockID);
		world.setBlock(i + 1, j + 18, k + 1, Block.stone.blockID);
		world.setBlock(i + 1, j + 18, k + 2, Block.stone.blockID);
		world.setBlock(i + 1, j + 18, k + 3, Block.stone.blockID);
		world.setBlock(i + 1, j + 18, k + 4, Block.stone.blockID);
		world.setBlock(i + 1, j + 18, k + 5, Block.stone.blockID);
		world.setBlock(i + 1, j + 18, k + 6, Block.stone.blockID);
		world.setBlock(i + 1, j + 18, k + 7, Block.stone.blockID);
		world.setBlock(i + 1, j + 18, k + 8, Block.stone.blockID);
		world.setBlock(i + 1, j + 18, k + 9, Block.stone.blockID);
		world.setBlock(i + 1, j + 18, k + 10, Block.stone.blockID);
		world.setBlock(i + 1, j + 18, k + 11, Block.stone.blockID);
		world.setBlock(i + 1, j + 18, k + 12, Block.stone.blockID);
		world.setBlock(i + 1, j + 18, k + 13, Block.stone.blockID);
		world.setBlock(i + 1, j + 18, k + 14, Block.stone.blockID);
		world.setBlock(i + 1, j + 18, k + 15, Block.stone.blockID);
		world.setBlock(i + 1, j + 18, k + 16, Block.stone.blockID);
		world.setBlock(i + 1, j + 18, k + 17, Block.stone.blockID);
		world.setBlock(i + 1, j + 18, k + 18, Block.stone.blockID);
		world.setBlock(i + 1, j + 18, k + 19, Block.stone.blockID);
		world.setBlock(i + 1, j + 18, k + 20, Block.stone.blockID);
		world.setBlock(i + 1, j + 18, k + 21, Block.stone.blockID);
		world.setBlock(i + 1, j + 18, k + 22, Block.stone.blockID);
		world.setBlock(i + 1, j + 18, k + 23, Block.stone.blockID);
		world.setBlock(i + 1, j + 18, k + 24, Block.stone.blockID);
		world.setBlock(i + 1, j + 18, k + 25, Block.stone.blockID);
		world.setBlock(i + 1, j + 18, k + 26, Block.stone.blockID);
		world.setBlock(i + 1, j + 18, k + 27, Block.stone.blockID);
		world.setBlock(i + 1, j + 18, k + 28, Block.stone.blockID);
		world.setBlock(i + 1, j + 18, k + 29, Block.stone.blockID);
		world.setBlock(i + 1, j + 18, k + 30, Block.stone.blockID);
		world.setBlock(i + 1, j + 18, k + 31, Block.stone.blockID);
		world.setBlock(i + 1, j + 18, k + 32, Block.stone.blockID);
		world.setBlock(i + 1, j + 18, k + 33, Block.stone.blockID);
		world.setBlock(i + 1, j + 18, k + 34, Block.stone.blockID);
		world.setBlock(i + 1, j + 19, k + 0, Block.stone.blockID);
		world.setBlock(i + 1, j + 19, k + 1, Block.stone.blockID);
		world.setBlock(i + 1, j + 19, k + 2, Block.stone.blockID);
		world.setBlock(i + 1, j + 19, k + 3, Block.stone.blockID);
		world.setBlock(i + 1, j + 19, k + 4, Block.stone.blockID);
		world.setBlock(i + 1, j + 19, k + 5, Block.stone.blockID);
		world.setBlock(i + 1, j + 19, k + 6, Block.stone.blockID);
		world.setBlock(i + 1, j + 19, k + 7, Block.stone.blockID);
		world.setBlock(i + 1, j + 19, k + 8, Block.stone.blockID);
		world.setBlock(i + 1, j + 19, k + 9, Block.stone.blockID);
		world.setBlock(i + 1, j + 19, k + 10, Block.stone.blockID);
		world.setBlock(i + 1, j + 19, k + 11, Block.stone.blockID);
		world.setBlock(i + 1, j + 19, k + 12, Block.stone.blockID);
		world.setBlock(i + 1, j + 19, k + 13, Block.stone.blockID);
		world.setBlock(i + 1, j + 19, k + 14, Block.stone.blockID);
		world.setBlock(i + 1, j + 19, k + 15, Block.stone.blockID);
		world.setBlock(i + 1, j + 19, k + 16, Block.stone.blockID);
		world.setBlock(i + 1, j + 19, k + 17, Block.stone.blockID);
		world.setBlock(i + 1, j + 19, k + 18, Block.stone.blockID);
		world.setBlock(i + 1, j + 19, k + 19, Block.stone.blockID);
		world.setBlock(i + 1, j + 19, k + 20, Block.stone.blockID);
		world.setBlock(i + 1, j + 19, k + 21, Block.stone.blockID);
		world.setBlock(i + 1, j + 19, k + 22, Block.stone.blockID);
		world.setBlock(i + 1, j + 19, k + 23, Block.stone.blockID);
		world.setBlock(i + 1, j + 19, k + 24, Block.stone.blockID);
		world.setBlock(i + 1, j + 19, k + 25, Block.stone.blockID);
		world.setBlock(i + 1, j + 19, k + 26, Block.stone.blockID);
		world.setBlock(i + 1, j + 19, k + 27, Block.stone.blockID);
		world.setBlock(i + 1, j + 19, k + 28, Block.stone.blockID);
		world.setBlock(i + 1, j + 19, k + 29, Block.stone.blockID);
		world.setBlock(i + 1, j + 19, k + 30, Block.stone.blockID);
		world.setBlock(i + 1, j + 19, k + 31, Block.stone.blockID);
		world.setBlock(i + 1, j + 19, k + 32, Block.stone.blockID);
		world.setBlock(i + 1, j + 19, k + 33, Block.stone.blockID);
		world.setBlock(i + 1, j + 19, k + 34, Block.stone.blockID);
		world.setBlock(i + 2, j + 0, k + 0, Block.stone.blockID);
		world.setBlock(i + 2, j + 0, k + 1, Block.stone.blockID);
		world.setBlock(i + 2, j + 0, k + 2, Block.stone.blockID);
		world.setBlock(i + 2, j + 0, k + 3, Block.stone.blockID);
		world.setBlock(i + 2, j + 0, k + 4, Block.stone.blockID);
		world.setBlock(i + 2, j + 0, k + 5, Block.stone.blockID);
		world.setBlock(i + 2, j + 0, k + 6, Block.stone.blockID);
		world.setBlock(i + 2, j + 0, k + 7, Block.stone.blockID);
		world.setBlock(i + 2, j + 0, k + 8, Block.stone.blockID);
		world.setBlock(i + 2, j + 0, k + 9, Block.stone.blockID);
		world.setBlock(i + 2, j + 0, k + 10, Block.stone.blockID);
		world.setBlock(i + 2, j + 0, k + 11, Block.stone.blockID);
		world.setBlock(i + 2, j + 0, k + 12, Block.stone.blockID);
		world.setBlock(i + 2, j + 0, k + 13, Block.stone.blockID);
		world.setBlock(i + 2, j + 0, k + 14, Block.stone.blockID);
		world.setBlock(i + 2, j + 0, k + 15, Block.stone.blockID);
		world.setBlock(i + 2, j + 0, k + 16, Block.stone.blockID);
		world.setBlock(i + 2, j + 0, k + 17, Block.stone.blockID);
		world.setBlock(i + 2, j + 0, k + 18, Block.stone.blockID);
		world.setBlock(i + 2, j + 0, k + 19, Block.stone.blockID);
		world.setBlock(i + 2, j + 0, k + 20, Block.stone.blockID);
		world.setBlock(i + 2, j + 0, k + 21, Block.stone.blockID);
		world.setBlock(i + 2, j + 0, k + 22, Block.stone.blockID);
		world.setBlock(i + 2, j + 0, k + 23, Block.stone.blockID);
		world.setBlock(i + 2, j + 0, k + 24, Block.stone.blockID);
		world.setBlock(i + 2, j + 0, k + 25, Block.stone.blockID);
		world.setBlock(i + 2, j + 0, k + 26, Block.stone.blockID);
		world.setBlock(i + 2, j + 0, k + 27, Block.stone.blockID);
		world.setBlock(i + 2, j + 0, k + 28, Block.stone.blockID);
		world.setBlock(i + 2, j + 0, k + 29, Block.stone.blockID);
		world.setBlock(i + 2, j + 0, k + 30, Block.stone.blockID);
		world.setBlock(i + 2, j + 0, k + 31, Block.stone.blockID);
		world.setBlock(i + 2, j + 0, k + 32, Block.stone.blockID);
		world.setBlock(i + 2, j + 0, k + 33, Block.stone.blockID);
		world.setBlock(i + 2, j + 0, k + 34, Block.stone.blockID);
		world.setBlock(i + 2, j + 1, k + 0, Block.stone.blockID);
		world.setBlock(i + 2, j + 1, k + 1, Block.stoneBrick.blockID);
		world.setBlock(i + 2, j + 1, k + 2, Block.stoneBrick.blockID);
		world.setBlock(i + 2, j + 1, k + 3, Block.stoneBrick.blockID);
		world.setBlock(i + 2, j + 1, k + 4, Block.stoneBrick.blockID);
		world.setBlock(i + 2, j + 1, k + 5, Block.stoneBrick.blockID);
		world.setBlock(i + 2, j + 1, k + 6, Block.stoneBrick.blockID);
		world.setBlock(i + 2, j + 1, k + 7, Block.stoneBrick.blockID);
		world.setBlock(i + 2, j + 1, k + 8, Block.stoneBrick.blockID);
		world.setBlock(i + 2, j + 1, k + 9, Block.stoneBrick.blockID);
		world.setBlock(i + 2, j + 1, k + 10, Block.stoneBrick.blockID);
		world.setBlock(i + 2, j + 1, k + 11, Block.stoneBrick.blockID);
		world.setBlock(i + 2, j + 1, k + 12, Block.stoneBrick.blockID);
		world.setBlock(i + 2, j + 1, k + 13, Block.stoneBrick.blockID);
		world.setBlock(i + 2, j + 1, k + 14, Block.stoneBrick.blockID);
		world.setBlock(i + 2, j + 1, k + 15, Block.stoneBrick.blockID);
		world.setBlock(i + 2, j + 1, k + 16, Block.stoneBrick.blockID);
		world.setBlock(i + 2, j + 1, k + 17, Block.stoneBrick.blockID);
		world.setBlock(i + 2, j + 1, k + 18, Block.stoneBrick.blockID);
		world.setBlock(i + 2, j + 1, k + 19, Block.stoneBrick.blockID);
		world.setBlock(i + 2, j + 1, k + 20, Block.stoneBrick.blockID);
		world.setBlock(i + 2, j + 1, k + 21, Block.stoneBrick.blockID);
		world.setBlock(i + 2, j + 1, k + 22, Block.stoneBrick.blockID);
		world.setBlock(i + 2, j + 1, k + 23, Block.stoneBrick.blockID);
		world.setBlock(i + 2, j + 1, k + 24, Block.stoneBrick.blockID);
		world.setBlock(i + 2, j + 1, k + 25, Block.stone.blockID);
		world.setBlock(i + 2, j + 1, k + 26, Block.stone.blockID);
		world.setBlock(i + 2, j + 1, k + 27, Block.stone.blockID);
		world.setBlock(i + 2, j + 1, k + 28, Block.stone.blockID);
		world.setBlock(i + 2, j + 1, k + 29, Block.stone.blockID);
		world.setBlock(i + 2, j + 1, k + 30, Block.stone.blockID);
		world.setBlock(i + 2, j + 1, k + 31, Block.stone.blockID);
		world.setBlock(i + 2, j + 1, k + 32, Block.stone.blockID);
		world.setBlock(i + 2, j + 1, k + 33, Block.stone.blockID);
		world.setBlock(i + 2, j + 1, k + 34, Block.stone.blockID);
		world.setBlock(i + 2, j + 2, k + 0, Block.stone.blockID);
		world.setBlock(i + 2, j + 2, k + 1, Block.stone.blockID);
		world.setBlock(i + 2, j + 2, k + 2, Block.stoneBrick.blockID);
		world.setBlock(i + 2, j + 2, k + 3, Block.stoneBrick.blockID);
		world.setBlock(i + 2, j + 2, k + 4, Block.stoneBrick.blockID);
		world.setBlock(i + 2, j + 2, k + 5, Block.stoneBrick.blockID);
		world.setBlock(i + 2, j + 2, k + 6, Block.stoneBrick.blockID);
		world.setBlock(i + 2, j + 2, k + 7, Block.stoneBrick.blockID);
		world.setBlock(i + 2, j + 2, k + 8, Block.stoneBrick.blockID);
		world.setBlock(i + 2, j + 2, k + 9, Block.stoneBrick.blockID);
		world.setBlock(i + 2, j + 2, k + 10, Block.stoneBrick.blockID);
		world.setBlock(i + 2, j + 2, k + 11, Block.stoneBrick.blockID);
		world.setBlock(i + 2, j + 2, k + 12, Block.stoneBrick.blockID);
		world.setBlock(i + 2, j + 2, k + 13, Block.stoneBrick.blockID);
		world.setBlock(i + 2, j + 2, k + 14, Block.stoneBrick.blockID);
		world.setBlock(i + 2, j + 2, k + 15, Block.stoneBrick.blockID);
		world.setBlock(i + 2, j + 2, k + 16, Block.stone.blockID);
		world.setBlock(i + 2, j + 2, k + 17, Block.stoneBrick.blockID);
		world.setBlock(i + 2, j + 2, k + 18, Block.stoneBrick.blockID);
		world.setBlock(i + 2, j + 2, k + 19, Block.stoneBrick.blockID);
		world.setBlock(i + 2, j + 2, k + 20, Block.stoneBrick.blockID);
		world.setBlock(i + 2, j + 2, k + 21, Block.stoneBrick.blockID);
		world.setBlock(i + 2, j + 2, k + 22, Block.stoneBrick.blockID);
		world.setBlock(i + 2, j + 2, k + 23, Block.stoneBrick.blockID);
		world.setBlock(i + 2, j + 2, k + 24, Block.stoneBrick.blockID);
		world.setBlock(i + 2, j + 2, k + 25, Block.stone.blockID);
		world.setBlock(i + 2, j + 2, k + 26, Block.stone.blockID);
		world.setBlock(i + 2, j + 2, k + 27, Block.stone.blockID);
		world.setBlock(i + 2, j + 2, k + 28, Block.stoneBrick.blockID);
		world.setBlock(i + 2, j + 2, k + 29, Block.stone.blockID);
		world.setBlock(i + 2, j + 2, k + 30, Block.stone.blockID);
		world.setBlock(i + 2, j + 2, k + 31, Block.stone.blockID);
		world.setBlock(i + 2, j + 2, k + 32, Block.stone.blockID);
		world.setBlock(i + 2, j + 2, k + 33, Block.stone.blockID);
		world.setBlock(i + 2, j + 2, k + 34, Block.stone.blockID);
		world.setBlock(i + 2, j + 3, k + 0, Block.stone.blockID);
		world.setBlock(i + 2, j + 3, k + 1, Block.stone.blockID);
		world.setBlock(i + 2, j + 3, k + 2, Block.stone.blockID);
		world.setBlockMetadataWithNotify(i + 2, j + 3, k + 4, Block.stoneSingleSlab.blockID, 5);
		world.setBlock(i + 2, j + 3, k + 5, Block.stairsStoneBrick.blockID);
		world.setBlockMetadataWithNotify(i + 2, j + 3, k + 6, Block.stoneSingleSlab.blockID, 5);
		world.setBlockMetadataWithNotify(i + 2, j + 3, k + 9, Block.stoneSingleSlab.blockID, 5);
		world.setBlock(i + 2, j + 3, k + 10, Block.stairsStoneBrick.blockID);
		world.setBlockMetadataWithNotify(i + 2, j + 3, k + 11, Block.stoneSingleSlab.blockID, 5);
		world.setBlockMetadataWithNotify(i + 2, j + 3, k + 14, Block.stoneSingleSlab.blockID, 5);
		world.setBlock(i + 2, j + 3, k + 15, Block.stone.blockID);
		world.setBlock(i + 2, j + 3, k + 16, Block.stone.blockID);
		world.setBlock(i + 2, j + 3, k + 17, Block.stone.blockID);
		world.setBlockMetadataWithNotify(i + 2, j + 3, k + 19, Block.stoneSingleSlab.blockID, 5);
		world.setBlock(i + 2, j + 3, k + 20, Block.stairsStoneBrick.blockID);
		world.setBlockMetadataWithNotify(i + 2, j + 3, k + 21, Block.stoneSingleSlab.blockID, 5);
		world.setBlock(i + 2, j + 3, k + 26, Block.stone.blockID);
		world.setBlock(i + 2, j + 3, k + 27, Block.stone.blockID);
		world.setBlock(i + 2, j + 3, k + 28, Block.stoneBrick.blockID);
		world.setBlock(i + 2, j + 3, k + 29, Block.stoneBrick.blockID);
		world.setBlock(i + 2, j + 3, k + 30, Block.stone.blockID);
		world.setBlock(i + 2, j + 3, k + 31, Block.stone.blockID);
		world.setBlock(i + 2, j + 3, k + 32, Block.stone.blockID);
		world.setBlock(i + 2, j + 3, k + 33, Block.stone.blockID);
		world.setBlock(i + 2, j + 3, k + 34, Block.stone.blockID);
		world.setBlock(i + 2, j + 4, k + 0, Block.stone.blockID);
		world.setBlock(i + 2, j + 4, k + 1, Block.stone.blockID);
		world.setBlock(i + 2, j + 4, k + 2, Block.stone.blockID);
		world.setBlock(i + 2, j + 4, k + 16, Block.stone.blockID);
		world.setBlock(i + 2, j + 4, k + 17, Block.stone.blockID);
		world.setBlock(i + 2, j + 4, k + 18, Block.stone.blockID);
		world.setBlock(i + 2, j + 4, k + 28, Block.stoneBrick.blockID);
		world.setBlock(i + 2, j + 4, k + 29, Block.stoneBrick.blockID);
		world.setBlock(i + 2, j + 4, k + 31, Block.stone.blockID);
		world.setBlock(i + 2, j + 4, k + 32, Block.stone.blockID);
		world.setBlock(i + 2, j + 4, k + 33, Block.stone.blockID);
		world.setBlock(i + 2, j + 4, k + 34, Block.stone.blockID);
		world.setBlock(i + 2, j + 5, k + 0, Block.stone.blockID);
		world.setBlock(i + 2, j + 5, k + 1, Block.stone.blockID);
		world.setBlock(i + 2, j + 5, k + 2, Block.stone.blockID);
		world.setBlock(i + 2, j + 5, k + 17, Block.stone.blockID);
		world.setBlock(i + 2, j + 5, k + 28, Block.stoneBrick.blockID);
		world.setBlock(i + 2, j + 5, k + 30, Block.stoneBrick.blockID);
		world.setBlock(i + 2, j + 5, k + 31, Block.stone.blockID);
		world.setBlock(i + 2, j + 5, k + 32, Block.stone.blockID);
		world.setBlock(i + 2, j + 5, k + 33, Block.stone.blockID);
		world.setBlock(i + 2, j + 5, k + 34, Block.stone.blockID);
		world.setBlock(i + 2, j + 6, k + 0, Block.stone.blockID);
		world.setBlock(i + 2, j + 6, k + 1, Block.stone.blockID);
		world.setBlock(i + 2, j + 6, k + 2, Block.stone.blockID);
		world.setBlock(i + 2, j + 6, k + 28, Block.stoneBrick.blockID);
		world.setBlock(i + 2, j + 6, k + 29, Block.stoneBrick.blockID);
		world.setBlock(i + 2, j + 6, k + 30, Block.stoneBrick.blockID);
		world.setBlock(i + 2, j + 6, k + 31, Block.stone.blockID);
		world.setBlock(i + 2, j + 6, k + 32, Block.stone.blockID);
		world.setBlock(i + 2, j + 6, k + 33, Block.stone.blockID);
		world.setBlock(i + 2, j + 6, k + 34, Block.stone.blockID);
		world.setBlock(i + 2, j + 7, k + 0, Block.stone.blockID);
		world.setBlock(i + 2, j + 7, k + 1, Block.stone.blockID);
		world.setBlock(i + 2, j + 7, k + 2, Block.stone.blockID);
		world.setBlock(i + 2, j + 7, k + 28, Block.stone.blockID);
		world.setBlock(i + 2, j + 7, k + 29, Block.stone.blockID);
		world.setBlock(i + 2, j + 7, k + 30, Block.stone.blockID);
		world.setBlock(i + 2, j + 7, k + 31, Block.stone.blockID);
		world.setBlock(i + 2, j + 7, k + 32, Block.stone.blockID);
		world.setBlock(i + 2, j + 7, k + 33, Block.stone.blockID);
		world.setBlock(i + 2, j + 7, k + 34, Block.stone.blockID);
		world.setBlock(i + 2, j + 8, k + 0, Block.stone.blockID);
		world.setBlock(i + 2, j + 8, k + 1, Block.stone.blockID);
		world.setBlock(i + 2, j + 8, k + 2, Block.stone.blockID);
		world.setBlock(i + 2, j + 8, k + 23, Block.stoneDoubleSlab.blockID);
		world.setBlock(i + 2, j + 8, k + 24, Block.stoneBrick.blockID);
		world.setBlock(i + 2, j + 8, k + 25, Block.stone.blockID);
		world.setBlock(i + 2, j + 8, k + 33, Block.stone.blockID);
		world.setBlock(i + 2, j + 8, k + 34, Block.stone.blockID);
		world.setBlock(i + 2, j + 9, k + 0, Block.stone.blockID);
		world.setBlock(i + 2, j + 9, k + 1, Block.stone.blockID);
		world.setBlock(i + 2, j + 9, k + 2, Block.stone.blockID);
		world.setBlock(i + 2, j + 9, k + 23, Block.stoneDoubleSlab.blockID);
		world.setBlock(i + 2, j + 9, k + 24, Block.stoneBrick.blockID);
		world.setBlock(i + 2, j + 9, k + 25, Block.stone.blockID);
		world.setBlock(i + 2, j + 9, k + 33, Block.stone.blockID);
		world.setBlock(i + 2, j + 9, k + 34, Block.stone.blockID);
		world.setBlock(i + 2, j + 10, k + 0, Block.stone.blockID);
		world.setBlock(i + 2, j + 10, k + 1, Block.stone.blockID);
		world.setBlock(i + 2, j + 10, k + 2, Block.stone.blockID);
		world.setBlock(i + 2, j + 10, k + 24, Block.stone.blockID);
		world.setBlock(i + 2, j + 10, k + 25, Block.stone.blockID);
		world.setBlock(i + 2, j + 10, k + 26, Block.stone.blockID);
		world.setBlock(i + 2, j + 10, k + 33, Block.stone.blockID);
		world.setBlock(i + 2, j + 10, k + 34, Block.stone.blockID);
		world.setBlock(i + 2, j + 11, k + 0, Block.stone.blockID);
		world.setBlock(i + 2, j + 11, k + 1, Block.stone.blockID);
		world.setBlock(i + 2, j + 11, k + 2, Block.stone.blockID);
		world.setBlock(i + 2, j + 11, k + 3, Block.stone.blockID);
		world.setBlock(i + 2, j + 11, k + 24, Block.stone.blockID);
		world.setBlock(i + 2, j + 11, k + 25, Block.stone.blockID);
		world.setBlock(i + 2, j + 11, k + 26, Block.stone.blockID);
		world.setBlock(i + 2, j + 11, k + 33, Block.stoneBrick.blockID);
		world.setBlock(i + 2, j + 11, k + 34, Block.stone.blockID);
		world.setBlock(i + 2, j + 12, k + 0, Block.stone.blockID);
		world.setBlock(i + 2, j + 12, k + 1, Block.stone.blockID);
		world.setBlock(i + 2, j + 12, k + 2, Block.stone.blockID);
		world.setBlock(i + 2, j + 12, k + 3, Block.stone.blockID);
		world.setBlock(i + 2, j + 12, k + 23, Block.stone.blockID);
		world.setBlock(i + 2, j + 12, k + 24, Block.stone.blockID);
		world.setBlock(i + 2, j + 12, k + 25, Block.stone.blockID);
		world.setBlock(i + 2, j + 12, k + 26, Block.stone.blockID);
		world.setBlock(i + 2, j + 12, k + 27, Block.stone.blockID);
		world.setBlock(i + 2, j + 12, k + 32, Block.stone.blockID);
		world.setBlock(i + 2, j + 12, k + 33, Block.stoneBrick.blockID);
		world.setBlock(i + 2, j + 12, k + 34, Block.stone.blockID);
		world.setBlock(i + 2, j + 13, k + 0, Block.stone.blockID);
		world.setBlock(i + 2, j + 13, k + 1, Block.stone.blockID);
		world.setBlock(i + 2, j + 13, k + 2, Block.stone.blockID);
		world.setBlock(i + 2, j + 13, k + 3, Block.stone.blockID);
		world.setBlock(i + 2, j + 13, k + 22, Block.stone.blockID);
		world.setBlock(i + 2, j + 13, k + 23, Block.stone.blockID);
		world.setBlock(i + 2, j + 13, k + 24, Block.stone.blockID);
		world.setBlock(i + 2, j + 13, k + 25, Block.stone.blockID);
		world.setBlock(i + 2, j + 13, k + 26, Block.stone.blockID);
		world.setBlock(i + 2, j + 13, k + 27, Block.stone.blockID);
		world.setBlock(i + 2, j + 13, k + 28, Block.stone.blockID);
		world.setBlock(i + 2, j + 13, k + 29, Block.stoneBrick.blockID);
		world.setBlock(i + 2, j + 13, k + 30, Block.stoneBrick.blockID);
		world.setBlock(i + 2, j + 13, k + 31, Block.stoneBrick.blockID);
		world.setBlock(i + 2, j + 13, k + 32, Block.stoneBrick.blockID);
		world.setBlock(i + 2, j + 13, k + 33, Block.stoneBrick.blockID);
		world.setBlock(i + 2, j + 13, k + 34, Block.stone.blockID);
		world.setBlock(i + 2, j + 14, k + 0, Block.stone.blockID);
		world.setBlock(i + 2, j + 14, k + 1, Block.stone.blockID);
		world.setBlock(i + 2, j + 14, k + 2, Block.stone.blockID);
		world.setBlock(i + 2, j + 14, k + 3, Block.stone.blockID);
		world.setBlock(i + 2, j + 14, k + 4, Block.stone.blockID);
		world.setBlock(i + 2, j + 14, k + 5, Block.stone.blockID);
		world.setBlock(i + 2, j + 14, k + 23, Block.stone.blockID);
		world.setBlock(i + 2, j + 14, k + 24, Block.stone.blockID);
		world.setBlock(i + 2, j + 14, k + 25, Block.stone.blockID);
		world.setBlock(i + 2, j + 14, k + 26, Block.stone.blockID);
		world.setBlock(i + 2, j + 14, k + 27, Block.stone.blockID);
		world.setBlock(i + 2, j + 14, k + 33, Block.stone.blockID);
		world.setBlock(i + 2, j + 14, k + 34, Block.stone.blockID);
		world.setBlock(i + 2, j + 15, k + 0, Block.stone.blockID);
		world.setBlock(i + 2, j + 15, k + 1, Block.stone.blockID);
		world.setBlock(i + 2, j + 15, k + 2, Block.stone.blockID);
		world.setBlock(i + 2, j + 15, k + 3, Block.stone.blockID);
		world.setBlock(i + 2, j + 15, k + 4, Block.stone.blockID);
		world.setBlock(i + 2, j + 15, k + 5, Block.stone.blockID);
		world.setBlock(i + 2, j + 15, k + 6, Block.stone.blockID);
		world.setBlock(i + 2, j + 15, k + 9, Block.stone.blockID);
		world.setBlock(i + 2, j + 15, k + 16, Block.stone.blockID);
		world.setBlock(i + 2, j + 15, k + 23, Block.stone.blockID);
		world.setBlock(i + 2, j + 15, k + 24, Block.stone.blockID);
		world.setBlock(i + 2, j + 15, k + 25, Block.stone.blockID);
		world.setBlock(i + 2, j + 15, k + 26, Block.stone.blockID);
		world.setBlock(i + 2, j + 15, k + 27, Block.stone.blockID);
		world.setBlock(i + 2, j + 15, k + 28, Block.stone.blockID);
		world.setBlock(i + 2, j + 15, k + 29, Block.stone.blockID);
		world.setBlock(i + 2, j + 15, k + 30, Block.stone.blockID);
		world.setBlock(i + 2, j + 15, k + 31, Block.stone.blockID);
		world.setBlock(i + 2, j + 15, k + 32, Block.stone.blockID);
		world.setBlock(i + 2, j + 15, k + 33, Block.stone.blockID);
		world.setBlock(i + 2, j + 15, k + 34, Block.stone.blockID);
		world.setBlock(i + 2, j + 16, k + 0, Block.stone.blockID);
		world.setBlock(i + 2, j + 16, k + 1, Block.stone.blockID);
		world.setBlock(i + 2, j + 16, k + 2, Block.stone.blockID);
		world.setBlock(i + 2, j + 16, k + 3, Block.stone.blockID);
		world.setBlock(i + 2, j + 16, k + 4, Block.stone.blockID);
		world.setBlock(i + 2, j + 16, k + 5, Block.stone.blockID);
		world.setBlock(i + 2, j + 16, k + 6, Block.stone.blockID);
		world.setBlock(i + 2, j + 16, k + 7, Block.stone.blockID);
		world.setBlock(i + 2, j + 16, k + 8, Block.stone.blockID);
		world.setBlock(i + 2, j + 16, k + 9, Block.stone.blockID);
		world.setBlock(i + 2, j + 16, k + 10, Block.stone.blockID);
		world.setBlock(i + 2, j + 16, k + 15, Block.stone.blockID);
		world.setBlock(i + 2, j + 16, k + 16, Block.stone.blockID);
		world.setBlock(i + 2, j + 16, k + 17, Block.stone.blockID);
		world.setBlock(i + 2, j + 16, k + 18, Block.stone.blockID);
		world.setBlock(i + 2, j + 16, k + 19, Block.stone.blockID);
		world.setBlock(i + 2, j + 16, k + 22, Block.stone.blockID);
		world.setBlock(i + 2, j + 16, k + 23, Block.stone.blockID);
		world.setBlock(i + 2, j + 16, k + 24, Block.stone.blockID);
		world.setBlock(i + 2, j + 16, k + 25, Block.stone.blockID);
		world.setBlock(i + 2, j + 16, k + 26, Block.stone.blockID);
		world.setBlock(i + 2, j + 16, k + 27, Block.stone.blockID);
		world.setBlock(i + 2, j + 16, k + 28, Block.stone.blockID);
		world.setBlock(i + 2, j + 16, k + 29, Block.stone.blockID);
		world.setBlock(i + 2, j + 16, k + 30, Block.stone.blockID);
		world.setBlock(i + 2, j + 16, k + 31, Block.stone.blockID);
		world.setBlock(i + 2, j + 16, k + 32, Block.stone.blockID);
		world.setBlock(i + 2, j + 16, k + 33, Block.stone.blockID);
		world.setBlock(i + 2, j + 16, k + 34, Block.stone.blockID);
		world.setBlock(i + 2, j + 17, k + 0, Block.stone.blockID);
		world.setBlock(i + 2, j + 17, k + 1, Block.stone.blockID);
		world.setBlock(i + 2, j + 17, k + 2, Block.stone.blockID);
		world.setBlock(i + 2, j + 17, k + 3, Block.stone.blockID);
		world.setBlock(i + 2, j + 17, k + 4, Block.stone.blockID);
		world.setBlock(i + 2, j + 17, k + 5, Block.stone.blockID);
		world.setBlock(i + 2, j + 17, k + 6, Block.stone.blockID);
		world.setBlock(i + 2, j + 17, k + 7, Block.stone.blockID);
		world.setBlock(i + 2, j + 17, k + 8, Block.stone.blockID);
		world.setBlock(i + 2, j + 17, k + 9, Block.stone.blockID);
		world.setBlock(i + 2, j + 17, k + 10, Block.stone.blockID);
		world.setBlock(i + 2, j + 17, k + 13, Block.stone.blockID);
		world.setBlock(i + 2, j + 17, k + 15, Block.stone.blockID);
		world.setBlock(i + 2, j + 17, k + 16, Block.stone.blockID);
		world.setBlock(i + 2, j + 17, k + 17, Block.stone.blockID);
		world.setBlock(i + 2, j + 17, k + 18, Block.stone.blockID);
		world.setBlock(i + 2, j + 17, k + 19, Block.stone.blockID);
		world.setBlock(i + 2, j + 17, k + 23, Block.stone.blockID);
		world.setBlock(i + 2, j + 17, k + 24, Block.stone.blockID);
		world.setBlock(i + 2, j + 17, k + 25, Block.stone.blockID);
		world.setBlock(i + 2, j + 17, k + 26, Block.stone.blockID);
		world.setBlock(i + 2, j + 17, k + 27, Block.stone.blockID);
		world.setBlock(i + 2, j + 17, k + 28, Block.stone.blockID);
		world.setBlock(i + 2, j + 17, k + 29, Block.stone.blockID);
		world.setBlock(i + 2, j + 17, k + 30, Block.stone.blockID);
		world.setBlock(i + 2, j + 17, k + 31, Block.stone.blockID);
		world.setBlock(i + 2, j + 17, k + 32, Block.stone.blockID);
		world.setBlock(i + 2, j + 17, k + 33, Block.stone.blockID);
		world.setBlock(i + 2, j + 17, k + 34, Block.stone.blockID);
		world.setBlock(i + 2, j + 18, k + 0, Block.stone.blockID);
		world.setBlock(i + 2, j + 18, k + 1, Block.stone.blockID);
		world.setBlock(i + 2, j + 18, k + 2, Block.stone.blockID);
		world.setBlock(i + 2, j + 18, k + 3, Block.stone.blockID);
		world.setBlock(i + 2, j + 18, k + 4, Block.stone.blockID);
		world.setBlock(i + 2, j + 18, k + 5, Block.stone.blockID);
		world.setBlock(i + 2, j + 18, k + 6, Block.stone.blockID);
		world.setBlock(i + 2, j + 18, k + 7, Block.stone.blockID);
		world.setBlock(i + 2, j + 18, k + 8, Block.stone.blockID);
		world.setBlock(i + 2, j + 18, k + 9, Block.stone.blockID);
		world.setBlock(i + 2, j + 18, k + 10, Block.stone.blockID);
		world.setBlock(i + 2, j + 18, k + 12, Block.stone.blockID);
		world.setBlock(i + 2, j + 18, k + 13, Block.stone.blockID);

		generate2(world, rand, i, j, k);
		return true;
	}

	public boolean generate2(World world, Random rand, int i, int j, int k) {
		world.setBlock(i + 2, j + 18, k + 14, Block.stone.blockID);
		world.setBlock(i + 2, j + 18, k + 15, Block.stone.blockID);
		world.setBlock(i + 2, j + 18, k + 16, Block.stone.blockID);
		world.setBlock(i + 2, j + 18, k + 17, Block.stone.blockID);
		world.setBlock(i + 2, j + 18, k + 18, Block.stone.blockID);
		world.setBlock(i + 2, j + 18, k + 19, Block.stone.blockID);
		world.setBlock(i + 2, j + 18, k + 20, Block.stone.blockID);
		world.setBlock(i + 2, j + 18, k + 21, Block.stone.blockID);
		world.setBlock(i + 2, j + 18, k + 23, Block.stone.blockID);
		world.setBlock(i + 2, j + 18, k + 24, Block.stone.blockID);
		world.setBlock(i + 2, j + 18, k + 25, Block.stone.blockID);
		world.setBlock(i + 2, j + 18, k + 26, Block.stone.blockID);
		world.setBlock(i + 2, j + 18, k + 27, Block.stone.blockID);
		world.setBlock(i + 2, j + 18, k + 28, Block.stone.blockID);
		world.setBlock(i + 2, j + 18, k + 29, Block.stone.blockID);
		world.setBlock(i + 2, j + 18, k + 30, Block.stone.blockID);
		world.setBlock(i + 2, j + 18, k + 31, Block.stone.blockID);
		world.setBlock(i + 2, j + 18, k + 32, Block.stone.blockID);
		world.setBlock(i + 2, j + 18, k + 33, Block.stone.blockID);
		world.setBlock(i + 2, j + 18, k + 34, Block.stone.blockID);
		world.setBlock(i + 2, j + 19, k + 0, Block.stone.blockID);
		world.setBlock(i + 2, j + 19, k + 1, Block.stone.blockID);
		world.setBlock(i + 2, j + 19, k + 2, Block.stone.blockID);
		world.setBlock(i + 2, j + 19, k + 3, Block.stone.blockID);
		world.setBlock(i + 2, j + 19, k + 4, Block.stone.blockID);
		world.setBlock(i + 2, j + 19, k + 5, Block.stone.blockID);
		world.setBlock(i + 2, j + 19, k + 6, Block.stone.blockID);
		world.setBlock(i + 2, j + 19, k + 7, Block.stone.blockID);
		world.setBlock(i + 2, j + 19, k + 8, Block.stone.blockID);
		world.setBlock(i + 2, j + 19, k + 9, Block.stone.blockID);
		world.setBlock(i + 2, j + 19, k + 10, Block.stone.blockID);
		world.setBlock(i + 2, j + 19, k + 11, Block.stone.blockID);
		world.setBlock(i + 2, j + 19, k + 12, Block.stone.blockID);
		world.setBlock(i + 2, j + 19, k + 13, Block.stone.blockID);
		world.setBlock(i + 2, j + 19, k + 14, Block.stone.blockID);
		world.setBlock(i + 2, j + 19, k + 15, Block.stone.blockID);
		world.setBlock(i + 2, j + 19, k + 16, Block.stone.blockID);
		world.setBlock(i + 2, j + 19, k + 17, Block.stone.blockID);
		world.setBlock(i + 2, j + 19, k + 18, Block.stone.blockID);
		world.setBlock(i + 2, j + 19, k + 19, Block.stone.blockID);
		world.setBlock(i + 2, j + 19, k + 20, Block.stone.blockID);
		world.setBlock(i + 2, j + 19, k + 21, Block.stone.blockID);
		world.setBlock(i + 2, j + 19, k + 22, Block.stone.blockID);
		world.setBlock(i + 2, j + 19, k + 23, Block.stone.blockID);
		world.setBlock(i + 2, j + 19, k + 24, Block.stone.blockID);
		world.setBlock(i + 2, j + 19, k + 25, Block.stone.blockID);
		world.setBlock(i + 2, j + 19, k + 26, Block.stone.blockID);
		world.setBlock(i + 2, j + 19, k + 27, Block.stone.blockID);
		world.setBlock(i + 2, j + 19, k + 28, Block.stone.blockID);
		world.setBlock(i + 2, j + 19, k + 29, Block.stone.blockID);
		world.setBlock(i + 2, j + 19, k + 30, Block.stone.blockID);
		world.setBlock(i + 2, j + 19, k + 31, Block.stone.blockID);
		world.setBlock(i + 2, j + 19, k + 32, Block.stone.blockID);
		world.setBlock(i + 2, j + 19, k + 33, Block.stone.blockID);
		world.setBlock(i + 2, j + 19, k + 34, Block.stone.blockID);
		world.setBlock(i + 3, j + 0, k + 0, Block.stone.blockID);
		world.setBlock(i + 3, j + 0, k + 1, Block.stone.blockID);
		world.setBlock(i + 3, j + 0, k + 2, Block.stone.blockID);
		world.setBlock(i + 3, j + 0, k + 3, Block.stone.blockID);
		world.setBlock(i + 3, j + 0, k + 4, Block.stone.blockID);
		world.setBlock(i + 3, j + 0, k + 5, Block.stone.blockID);
		world.setBlock(i + 3, j + 0, k + 6, Block.stone.blockID);
		world.setBlock(i + 3, j + 0, k + 7, Block.stone.blockID);
		world.setBlock(i + 3, j + 0, k + 8, Block.stone.blockID);
		world.setBlock(i + 3, j + 0, k + 9, Block.stone.blockID);
		world.setBlock(i + 3, j + 0, k + 10, Block.stone.blockID);
		world.setBlock(i + 3, j + 0, k + 11, Block.stone.blockID);
		world.setBlock(i + 3, j + 0, k + 12, Block.stone.blockID);
		world.setBlock(i + 3, j + 0, k + 13, Block.stone.blockID);
		world.setBlock(i + 3, j + 0, k + 14, Block.stone.blockID);
		world.setBlock(i + 3, j + 0, k + 15, Block.stone.blockID);
		world.setBlock(i + 3, j + 0, k + 16, Block.stone.blockID);
		world.setBlock(i + 3, j + 0, k + 17, Block.stone.blockID);
		world.setBlock(i + 3, j + 0, k + 18, Block.stone.blockID);
		world.setBlock(i + 3, j + 0, k + 19, Block.stone.blockID);
		world.setBlock(i + 3, j + 0, k + 20, Block.stone.blockID);
		world.setBlock(i + 3, j + 0, k + 21, Block.stone.blockID);
		world.setBlock(i + 3, j + 0, k + 22, Block.stone.blockID);
		world.setBlock(i + 3, j + 0, k + 23, Block.stone.blockID);
		world.setBlock(i + 3, j + 0, k + 24, Block.stone.blockID);
		world.setBlock(i + 3, j + 0, k + 25, Block.stone.blockID);
		world.setBlock(i + 3, j + 0, k + 26, Block.stone.blockID);
		world.setBlock(i + 3, j + 0, k + 27, Block.stone.blockID);
		world.setBlock(i + 3, j + 0, k + 28, Block.stone.blockID);
		world.setBlock(i + 3, j + 0, k + 29, Block.stone.blockID);
		world.setBlock(i + 3, j + 0, k + 30, Block.stone.blockID);
